Workbook

Sheet Home

Sheet Tetris
A1: 1 | B1: 1 | C1: 1 | D1: 1 | E1: 1 | F1: 1 | G1: 1 | H1: 1 | I1: 1 | J1: 1 | K1: 1 | L1: 1 | M1: 1 | N1: 1 | O1: 1 | P1: 1 | Q1: 1 | R1: 1 | S1: 1 | T1: 1 | U1: 1 | V1: 1 | W1: 1
A2: 1 | B2: 1 | C2: 1 | D2: Tetris | N2: 1 | O2: 1 | P2: 1 | Q2: 1 | R2: 1 | S2: 1 | T2: 1 | U2: 1 | V2: 1 | W2: 1
A3: 1 | B3: 1 | C3: 1 | D3: 1 | E3: 1 | F3: 1 | G3: 1 | H3: 1 | I3: 1 | J3: 1 | K3: 1 | L3: 1 | M3: 1 | N3: 1 | O3: 1 | P3: 1 | Q3: 1 | R3: 1 | S3: 1 | T3: 1 | U3: 1 | V3: 1 | W3: 1
A4: 1 | B4: 1 | C4: 1 | D4: 1 | E4: 1 | F4: 1 | G4: 1 | H4: 1 | I4: 1 | J4: 1 | K4: 1 | L4: 1 | M4: 1 | N4: 1 | O4: 1 | P4: 1 | Q4: 1 | R4: 1 | S4: 1 | T4: 1 | U4: 1 | V4: 1 | W4: 1
A5: 1 | B5: 1 | C5: 1 | D5: 1 | E5: 1 | F5: 1 | G5: 1 | H5: 1 | I5: 1 | J5: 1 | K5: 1 | L5: 1 | M5: 1 | N5: 1 | O5: 1 | P5: 1 | Q5: 1 | R5: 1 | S5: 1 | T5: 1 | U5: 1 | V5: 1 | W5: 1
A6: 1 | B6: 1 | C6: 1 | D6: 1 | E6: 1 | F6: 1 | G6: 1 | H6: 1 | I6: 1 | J6: 1 | K6: 1 | L6: 1 | M6: 1 | N6: 1 | O6: 1 | P6: 1 | Q6: 1 | R6: 1 | S6: 1 | T6: 1 | U6: 1 | V6: 1 | W6: 1
A7: 1 | B7: 1 | C7: 1 | D7: 0 | E7: 0 | F7: 0 | G7: 1 | H7: 1 | I7: 1 | J7: 0 | K7: 0 | L7: 0 | M7: 0 | N7: 1 | O7: 1 | P7: 1 | Q7: 1 | R7: 1 | S7: 1 | T7: 1 | U7: 1 | V7: 1 | W7: 1
A8: 1 | B8: 1 | C8: 1 | D8: 0 | E8: 0 | F8: 0 | G8: 0 | H8: 1 | I8: 0 | J8: 0 | K8: 0 | L8: 0 | M8: 0 | N8: 1 | O8: 1 | P8: 1 | Q8: 1 | R8: 1 | S8: 1 | T8: 1 | U8: 1 | V8: 1 | W8: 1
A9: 1 | B9: 1 | C9: 1 | D9: 0 | E9: 1 | F9: 1 | G9: 1 | H9: 0 | I9: 0 | J9: 0 | K9: 0 | L9: 0 | M9: 0 | N9: 1 | O9: 1 | P9: 1 | V9: 1 | W9: 1
A10: 1 | B10: 1 | C10: 1 | D10: 0 | E10: 0 | F10: 0 | G10: 1 | H10: 0 | I10: 0 | J10: 0 | K10: 0 | L10: 0 | M10: 0 | N10: 1 | O10: 1 | P10: 1 | R10: Left | S10: X | T10: Right | V10: 1 | W10: 1
A11: 1 | B11: 1 | C11: 1 | D11: 0 | E11: 0 | F11: 0 | G11: 0 | H11: 0 | I11: 0 | J11: 0 | K11: 0 | L11: 0 | M11: 0 | N11: 1 | O11: 1 | P11: 1 | S11: Rotate | V11: 1 | W11: 1
A12: 1 | B12: 1 | C12: 1 | D12: 0 | E12: 0 | F12: 0 | G12: 0 | H12: 0 | I12: 0 | J12: 0 | K12: 0 | L12: 0 | M12: 0 | N12: 1 | O12: 1 | P12: 1 | V12: 1 | W12: 1
A13: 1 | B13: 1 | C13: 1 | D13: 0 | E13: 0 | F13: 0 | G13: 0 | H13: 0 | I13: 0 | J13: 0 | K13: 0 | L13: 0 | M13: 0 | N13: 1 | O13: 1 | P13: 1 | Q13: 1 | R13: 1 | S13: 1 | T13: 1 | U13: 1 | V13: 1 | W13: 1
A14: 1 | B14: 1 | C14: 1 | D14: 0 | E14: 0 | F14: 0 | G14: 0 | H14: 0 | I14: 0 | J14: 0 | K14: 0 | L14: 0 | M14: 0 | N14: 1 | O14: 1 | P14: 1 | Q14: 1 | R14: 1 | S14: 1 | T14: 1 | U14: 1 | V14: 1 | W14: 1
A15: 1 | B15: 1 | C15: 1 | D15: 0 | E15: 0 | F15: 0 | G15: 0 | H15: 0 | I15: 0 | J15: 0 | K15: 0 | L15: 0 | M15: 0 | N15: 1 | O15: 1 | P15: 1 | Q15: 1 | R15: 1 | S15: 1 | T15: 1 | U15: 1 | V15: 1 | W15: 1
A16: 1 | B16: 1 | C16: 1 | D16: 0 | E16: 0 | F16: 0 | G16: 0 | H16: 0 | I16: 0 | J16: 0 | K16: 0 | L16: 0 | M16: 0 | N16: 1 | O16: 1 | P16: 1 | V16: 1 | W16: 1
A17: 1 | B17: 1 | C17: 1 | D17: 0 | E17: 0 | F17: 0 | G17: 0 | H17: 0 | I17: 0 | J17: 0 | K17: 0 | L17: 0 | M17: 0 | N17: 1 | O17: 1 | P17: 1 | R17: Score: | T17: 0 | V17: 1 | W17: 1
A18: 1 | B18: 1 | C18: 1 | D18: 1 | E18: 1 | F18: 0 | G18: 0 | H18: 0 | I18: 0 | J18: 0 | K18: 0 | L18: 0 | M18: 0 | N18: 1 | O18: 1 | P18: 1 | V18: 1 | W18: 1
A19: 1 | B19: 1 | C19: 1 | D19: 1 | E19: 1 | F19: 0 | G19: 0 | H19: 0 | I19: 0 | J19: 0 | K19: 0 | L19: 0 | M19: 0 | N19: 1 | O19: 1 | P19: 1 | Q19: 1 | R19: 1 | S19: 1 | T19: 1 | U19: 1 | V19: 1 | W19: 1
A20: 1 | B20: 1 | C20: 1 | D20: 1 | E20: 1 | F20: 0 | G20: 0 | H20: 0 | I20: 0 | J20: 0 | K20: 0 | L20: 0 | M20: 0 | N20: 1 | O20: 1 | P20: 1 | Q20: 1 | S20: 1 | T20: 1 | U20: 1 | V20: 1 | W20: 1
A21: 1 | B21: 1 | C21: 1 | D21: 1 | E21: 1 | F21: 0 | G21: 0 | H21: 0 | I21: 0 | J21: 0 | K21: 0 | L21: 0 | M21: 0 | N21: 1 | O21: 1 | P21: 1 | Q21: 1 | R21: 1 | S21: 1 | T21: 1 | U21: 1 | V21: 1 | W21: 1
A22: 1 | B22: 1 | C22: 1 | D22: 1 | E22: 1 | F22: 0 | G22: 1 | H22: 0 | I22: 0 | J22: 0 | K22: 0 | L22: 0 | M22: 0 | N22: 1 | O22: 1 | P22: 1 | Q22: 1 | R22: 1 | S22: 1 | T22: 1 | U22: 1 | V22: 1 | W22: 1
A23: 1 | B23: 1 | C23: 1 | D23: 1 | E23: 1 | F23: 1 | G23: 1 | H23: 0 | I23: 0 | J23: 0 | K23: 0 | L23: 0 | M23: 0 | N23: 1 | O23: 1 | P23: 1 | Q23: 1 | R23: 1 | S23: 1 | T23: 1 | U23: 1 | V23: 1 | W23: 1
A24: 1 | B24: 1 | C24: 1 | D24: 1 | E24: 1 | F24: 1 | G24: 1 | H24: 1 | I24: 0 | J24: 0 | K24: 0 | L24: 0 | M24: 0 | N24: 1 | O24: 1 | P24: 1 | S24: Quit | V24: 1 | W24: 1
A25: 1 | B25: 1 | C25: 1 | D25: 1 | E25: 1 | F25: 1 | G25: 0 | H25: 1 | I25: 0 | J25: 0 | K25: 0 | L25: 0 | M25: 0 | N25: 1 | O25: 1 | P25: 1 | Q25: 1 | R25: 1 | S25: 1 | T25: 1 | U25: 1 | V25: 1 | W25: 1
A26: 1 | B26: 1 | C26: 1 | D26: 0 | E26: 1 | F26: 1 | G26: 1 | H26: 1 | I26: 0 | J26: 0 | K26: 0 | L26: 0 | M26: 0 | N26: 1 | O26: 1 | P26: 1 | Q26: 1 | R26: 1 | S26: 1 | T26: 1 | U26: 1 | V26: 1 | W26: 1
A27: 1 | B27: 1 | C27: 1 | D27: 1 | E27: 1 | F27: 1 | G27: 1 | H27: 1 | I27: 1 | J27: 1 | K27: 1 | L27: 1 | M27: 1 | N27: 1 | O27: 1 | P27: 1 | Q27: 1 | R27: 1 | S27: 1 | T27: 1 | U27: Back
A28: 1 | B28: 1 | C28: 1 | D28: 1 | E28: 1 | F28: 1 | G28: 1 | H28: 1 | I28: 1 | J28: 1 | K28: 1 | L28: 1 | M28: 1 | N28: 1 | O28: 1 | P28: 1 | Q28: 1 | R28: 1 | S28: 1 | T28: 1
A29: 1 | B29: 1 | C29: 1 | D29: 1 | E29: 1 | F29: 1 | G29: 1 | H29: 1 | I29: 1 | J29: 1 | K29: 1 | L29: 1 | M29: 1 | N29: 1 | O29: 1 | P29: 1 | Q29: 1 | R29: 1 | S29: 1 | T29: 1

Sheet FlappyBird
B1: FLAPPY | U1: Hi-Score: | X1: =IF(F4>X1, F4, X1) -> 170
B2: BIRD | J2: Click fn+F9 to move
K3: =IF(AND(V4=0, Backend!K31<>-1), "GAME OVER", "")
D4: Score: | F4: =QUOTIENT(Backend!K31, 4) -> 0 | T4: Lives: | V4: =IF(V20=TRUE, IF(AND(OR(COUNTIF(F5:F19,5)>0,Backend!K35>14,Backend!K35<0), V4>0), V4-1, V4), 3) -> 0
D5: {=_xlfn.LET(_xlpm.shift, Backend!$K$31, _xlpm.shape, INDEX(Backend!2:2,COLUMN(Backend!A2)+_xlpm.shift), IF(Backend!$K$31=-1, 0, _xlpm.shape))} -> 0 | E5: {=_xlfn.LET(_xlpm.shift, Backend!$K$31, _xlpm.shape, INDEX(Backend!2:2,COLUMN(Backend!B2)+_xlpm.shift), IF($AA$19=-1, 0, _xlpm.shape))} -> 0 | F5: {=_xlfn.LET(_xlpm.shift, Backend!$K$31, _xlpm.up, Backend!K35, _xlpm.shape, IF(_xlpm.up=14, IF(AND(_xlpm.up=14, INDEX(Backend!2:2,COLUMN(Backend!C2)+_xlpm.shift)=1), 5, " ∎"), INDEX(Backend!2:2,COLUMN(Backend!C2)+_xlpm.shift)), _xlpm.shape)} -> 0 | G5: {=_xlfn.LET(_xlpm.shift, Backend!$K$31, _xlpm.shape, INDEX(Backend!2:2,COLUMN(Backend!D2)+_xlpm.shift), _xlpm.shape)} -> 0 | H5: {=_xlfn.LET(_xlpm.shift, Backend!$K$31, _xlpm.shape, INDEX(Backend!2:2,COLUMN(Backend!E2)+_xlpm.shift), _xlpm.shape)} -> 0 | I5: {=_xlfn.LET(_xlpm.shift, Backend!$K$31, _xlpm.shape, INDEX(Backend!2:2,COLUMN(Backend!F2)+_xlpm.shift), _xlpm.shape)} -> 1 | J5: {=_xlfn.LET(_xlpm.shift, Backend!$K$31, _xlpm.shape, INDEX(Backend!2:2,COLUMN(Backend!G2)+_xlpm.shift), _xlpm.shape)} -> 1 | K5: {=_xlfn.LET(_xlpm.shift, Backend!$K$31, _xlpm.shape, INDEX(Backend!2:2,COLUMN(Backend!H2)+_xlpm.shift), _xlpm.shape)} -> 0 | L5: {=_xlfn.LET(_xlpm.shift, Backend!$K$31, _xlpm.shape, INDEX(Backend!2:2,COLUMN(Backend!I2)+_xlpm.shift), _xlpm.shape)} -> 0 | M5: {=_xlfn.LET(_xlpm.shift, Backend!$K$31, _xlpm.shape, INDEX(Backend!2:2,COLUMN(Backend!J2)+_xlpm.shift), _xlpm.shape)} -> 1 | N5: {=_xlfn.LET(_xlpm.shift, Backend!$K$31, _xlpm.shape, INDEX(Backend!2:2,COLUMN(Backend!K2)+_xlpm.shift), _xlpm.shape)} -> 1 | ... V5: {=_xlfn.LET(_xlpm.shift, Backend!$K$31, _xlpm.shape, INDEX(Backend!2:2,COLUMN(Backend!S2)+_xlpm.shift), _xlpm.shape)} -> 1
D6: {=_xlfn.LET(_xlpm.shift, Backend!$K$31, _xlpm.shape, INDEX(Backend!3:3,COLUMN(Backend!A3)+_xlpm.shift), IF(Backend!$K$31=-1, 0, _xlpm.shape))} -> 0 | E6: {=_xlfn.LET(_xlpm.shift, Backend!$K$31, _xlpm.shape, INDEX(Backend!3:3,COLUMN(Backend!B3)+_xlpm.shift), IF($AA$19=-1, 0, _xlpm.shape))} -> 0 | F6: {=_xlfn.LET(_xlpm.shift, Backend!$K$31, _xlpm.up, Backend!K35, _xlpm.shape, IF(_xlpm.up=13, IF(AND(_xlpm.up=13, INDEX(Backend!3:3,COLUMN(Backend!C3)+_xlpm.shift)=1), 5, " ∎"), INDEX(Backend!3:3,COLUMN(Backend!C3)+_xlpm.shift)), _xlpm.shape)} -> 0 | G6: {=_xlfn.LET(_xlpm.shift, Backend!$K$31, _xlpm.shape, INDEX(Backend!3:3,COLUMN(Backend!D3)+_xlpm.shift), _xlpm.shape)} -> 0 | H6: {=_xlfn.LET(_xlpm.shift, Backend!$K$31, _xlpm.shape, INDEX(Backend!3:3,COLUMN(Backend!E3)+_xlpm.shift), _xlpm.shape)} -> 0 | I6: {=_xlfn.LET(_xlpm.shift, Backend!$K$31, _xlpm.shape, INDEX(Backend!3:3,COLUMN(Backend!F3)+_xlpm.shift), _xlpm.shape)} -> 1 | J6: {=_xlfn.LET(_xlpm.shift, Backend!$K$31, _xlpm.shape, INDEX(Backend!3:3,COLUMN(Backend!G3)+_xlpm.shift), _xlpm.shape)} -> 1 | K6: {=_xlfn.LET(_xlpm.shift, Backend!$K$31, _xlpm.shape, INDEX(Backend!3:3,COLUMN(Backend!H3)+_xlpm.shift), _xlpm.shape)} -> 0 | L6: {=_xlfn.LET(_xlpm.shift, Backend!$K$31, _xlpm.shape, INDEX(Backend!3:3,COLUMN(Backend!I3)+_xlpm.shift), _xlpm.shape)} -> 0 | M6: {=_xlfn.LET(_xlpm.shift, Backend!$K$31, _xlpm.shape, INDEX(Backend!3:3,COLUMN(Backend!J3)+_xlpm.shift), _xlpm.shape)} -> 1 | N6: {=_xlfn.LET(_xlpm.shift, Backend!$K$31, _xlpm.shape, INDEX(Backend!3:3,COLUMN(Backend!K3)+_xlpm.shift), _xlpm.shape)} -> 1 | ... V6: {=_xlfn.LET(_xlpm.shift, Backend!$K$31, _xlpm.shape, INDEX(Backend!3:3,COLUMN(Backend!S3)+_xlpm.shift), _xlpm.shape)} -> 1
D7: {=_xlfn.LET(_xlpm.shift, Backend!$K$31, _xlpm.shape, INDEX(Backend!4:4,COLUMN(Backend!A4)+_xlpm.shift), IF(Backend!$K$31=-1, 0, _xlpm.shape))} -> 0 | E7: {=_xlfn.LET(_xlpm.shift, Backend!$K$31, _xlpm.shape, INDEX(Backend!4:4,COLUMN(Backend!B4)+_xlpm.shift), IF($AA$19=-1, 0, _xlpm.shape))} -> 0 | F7: {=_xlfn.LET(_xlpm.shift, Backend!$K$31, _xlpm.up, Backend!K35, _xlpm.shape, IF(_xlpm.up=12, IF(AND(_xlpm.up=12, INDEX(Backend!4:4,COLUMN(Backend!C4)+_xlpm.shift)=1), 5, " ∎"), INDEX(Backend!4:4,COLUMN(Backend!C4)+_xlpm.shift)), _xlpm.shape)} -> 0 | G7: {=_xlfn.LET(_xlpm.shift, Backend!$K$31, _xlpm.shape, INDEX(Backend!4:4,COLUMN(Backend!D4)+_xlpm.shift), _xlpm.shape)} -> 0 | H7: {=_xlfn.LET(_xlpm.shift, Backend!$K$31, _xlpm.shape, INDEX(Backend!4:4,COLUMN(Backend!E4)+_xlpm.shift), _xlpm.shape)} -> 0 | I7: {=_xlfn.LET(_xlpm.shift, Backend!$K$31, _xlpm.shape, INDEX(Backend!4:4,COLUMN(Backend!F4)+_xlpm.shift), _xlpm.shape)} -> 1 | J7: {=_xlfn.LET(_xlpm.shift, Backend!$K$31, _xlpm.shape, INDEX(Backend!4:4,COLUMN(Backend!G4)+_xlpm.shift), _xlpm.shape)} -> 1 | K7: {=_xlfn.LET(_xlpm.shift, Backend!$K$31, _xlpm.shape, INDEX(Backend!4:4,COLUMN(Backend!H4)+_xlpm.shift), _xlpm.shape)} -> 0 | L7: {=_xlfn.LET(_xlpm.shift, Backend!$K$31, _xlpm.shape, INDEX(Backend!4:4,COLUMN(Backend!I4)+_xlpm.shift), _xlpm.shape)} -> 0 | M7: {=_xlfn.LET(_xlpm.shift, Backend!$K$31, _xlpm.shape, INDEX(Backend!4:4,COLUMN(Backend!J4)+_xlpm.shift), _xlpm.shape)} -> 1 | N7: {=_xlfn.LET(_xlpm.shift, Backend!$K$31, _xlpm.shape, INDEX(Backend!4:4,COLUMN(Backend!K4)+_xlpm.shift), _xlpm.shape)} -> 1 | ... V7: {=_xlfn.LET(_xlpm.shift, Backend!$K$31, _xlpm.shape, INDEX(Backend!4:4,COLUMN(Backend!S4)+_xlpm.shift), _xlpm.shape)} -> 0
D8: {=_xlfn.LET(_xlpm.shift, Backend!$K$31, _xlpm.shape, INDEX(Backend!5:5,COLUMN(Backend!A5)+_xlpm.shift), IF(Backend!$K$31=-1, 0, _xlpm.shape))} -> 0 | E8: {=_xlfn.LET(_xlpm.shift, Backend!$K$31, _xlpm.shape, INDEX(Backend!5:5,COLUMN(Backend!B5)+_xlpm.shift), IF($AA$19=-1, 0, _xlpm.shape))} -> 0 | F8: {=_xlfn.LET(_xlpm.shift, Backend!$K$31, _xlpm.up, Backend!K35, _xlpm.shape, IF(_xlpm.up=11, IF(AND(_xlpm.up=11, INDEX(Backend!5:5,COLUMN(Backend!C5)+_xlpm.shift)=1), 5, " ∎"), INDEX(Backend!5:5,COLUMN(Backend!C5)+_xlpm.shift)), _xlpm.shape)} -> 0 | G8: {=_xlfn.LET(_xlpm.shift, Backend!$K$31, _xlpm.shape, INDEX(Backend!5:5,COLUMN(Backend!D5)+_xlpm.shift), _xlpm.shape)} -> 0 | H8: {=_xlfn.LET(_xlpm.shift, Backend!$K$31, _xlpm.shape, INDEX(Backend!5:5,COLUMN(Backend!E5)+_xlpm.shift), _xlpm.shape)} -> 0 | I8: {=_xlfn.LET(_xlpm.shift, Backend!$K$31, _xlpm.shape, INDEX(Backend!5:5,COLUMN(Backend!F5)+_xlpm.shift), _xlpm.shape)} -> 1 | J8: {=_xlfn.LET(_xlpm.shift, Backend!$K$31, _xlpm.shape, INDEX(Backend!5:5,COLUMN(Backend!G5)+_xlpm.shift), _xlpm.shape)} -> 1 | K8: {=_xlfn.LET(_xlpm.shift, Backend!$K$31, _xlpm.shape, INDEX(Backend!5:5,COLUMN(Backend!H5)+_xlpm.shift), _xlpm.shape)} -> 0 | L8: {=_xlfn.LET(_xlpm.shift, Backend!$K$31, _xlpm.shape, INDEX(Backend!5:5,COLUMN(Backend!I5)+_xlpm.shift), _xlpm.shape)} -> 0 | M8: {=_xlfn.LET(_xlpm.shift, Backend!$K$31, _xlpm.shape, INDEX(Backend!5:5,COLUMN(Backend!J5)+_xlpm.shift), _xlpm.shape)} -> 1 | N8: {=_xlfn.LET(_xlpm.shift, Backend!$K$31, _xlpm.shape, INDEX(Backend!5:5,COLUMN(Backend!K5)+_xlpm.shift), _xlpm.shape)} -> 1 | ... V8: {=_xlfn.LET(_xlpm.shift, Backend!$K$31, _xlpm.shape, INDEX(Backend!5:5,COLUMN(Backend!S5)+_xlpm.shift), _xlpm.shape)} -> 0
D9: {=_xlfn.LET(_xlpm.shift, Backend!$K$31, _xlpm.shape, INDEX(Backend!6:6,COLUMN(Backend!A6)+_xlpm.shift), IF(Backend!$K$31=-1, 0, _xlpm.shape))} -> 0 | E9: {=_xlfn.LET(_xlpm.shift, Backend!$K$31, _xlpm.shape, INDEX(Backend!6:6,COLUMN(Backend!B6)+_xlpm.shift), IF($AA$19=-1, 0, _xlpm.shape))} -> 0 | F9: {=_xlfn.LET(_xlpm.shift, Backend!$K$31, _xlpm.up, Backend!K35, _xlpm.shape, IF(_xlpm.up=10, IF(AND(_xlpm.up=10, INDEX(Backend!6:6,COLUMN(Backend!C6)+_xlpm.shift)=1), 5, " ∎"), INDEX(Backend!6:6,COLUMN(Backend!C6)+_xlpm.shift)), _xlpm.shape)} -> 0 | G9: {=_xlfn.LET(_xlpm.shift, Backend!$K$31, _xlpm.shape, INDEX(Backend!6:6,COLUMN(Backend!D6)+_xlpm.shift), _xlpm.shape)} -> 0 | H9: {=_xlfn.LET(_xlpm.shift, Backend!$K$31, _xlpm.shape, INDEX(Backend!6:6,COLUMN(Backend!E6)+_xlpm.shift), _xlpm.shape)} -> 0 | I9: {=_xlfn.LET(_xlpm.shift, Backend!$K$31, _xlpm.shape, INDEX(Backend!6:6,COLUMN(Backend!F6)+_xlpm.shift), _xlpm.shape)} -> 1 | J9: {=_xlfn.LET(_xlpm.shift, Backend!$K$31, _xlpm.shape, INDEX(Backend!6:6,COLUMN(Backend!G6)+_xlpm.shift), _xlpm.shape)} -> 1 | K9: {=_xlfn.LET(_xlpm.shift, Backend!$K$31, _xlpm.shape, INDEX(Backend!6:6,COLUMN(Backend!H6)+_xlpm.shift), _xlpm.shape)} -> 0 | L9: {=_xlfn.LET(_xlpm.shift, Backend!$K$31, _xlpm.shape, INDEX(Backend!6:6,COLUMN(Backend!I6)+_xlpm.shift), _xlpm.shape)} -> 0 | M9: {=_xlfn.LET(_xlpm.shift, Backend!$K$31, _xlpm.shape, INDEX(Backend!6:6,COLUMN(Backend!J6)+_xlpm.shift), _xlpm.shape)} -> 0 | N9: {=_xlfn.LET(_xlpm.shift, Backend!$K$31, _xlpm.shape, INDEX(Backend!6:6,COLUMN(Backend!K6)+_xlpm.shift), _xlpm.shape)} -> 0 | ... V9: {=_xlfn.LET(_xlpm.shift, Backend!$K$31, _xlpm.shape, INDEX(Backend!6:6,COLUMN(Backend!S6)+_xlpm.shift), _xlpm.shape)} -> 0
D10: {=_xlfn.LET(_xlpm.shift, Backend!$K$31, _xlpm.shape, INDEX(Backend!7:7,COLUMN(Backend!A7)+_xlpm.shift), IF(Backend!$K$31=-1, 0, _xlpm.shape))} -> 0 | E10: {=_xlfn.LET(_xlpm.shift, Backend!$K$31, _xlpm.shape, INDEX(Backend!7:7,COLUMN(Backend!B7)+_xlpm.shift), IF($AA$19=-1, 0, _xlpm.shape))} -> 0 | F10: {=_xlfn.LET(_xlpm.shift, Backend!$K$31, _xlpm.up, Backend!K35, _xlpm.shape, IF(_xlpm.up=9, IF(AND(_xlpm.up=9, INDEX(Backend!7:7,COLUMN(Backend!C7)+_xlpm.shift)=1), 5, " ∎"), INDEX(Backend!7:7,COLUMN(Backend!C7)+_xlpm.shift)), _xlpm.shape)} -> 0 | G10: {=_xlfn.LET(_xlpm.shift, Backend!$K$31, _xlpm.shape, INDEX(Backend!7:7,COLUMN(Backend!D7)+_xlpm.shift), _xlpm.shape)} -> 0 | H10: {=_xlfn.LET(_xlpm.shift, Backend!$K$31, _xlpm.shape, INDEX(Backend!7:7,COLUMN(Backend!E7)+_xlpm.shift), _xlpm.shape)} -> 0 | I10: {=_xlfn.LET(_xlpm.shift, Backend!$K$31, _xlpm.shape, INDEX(Backend!7:7,COLUMN(Backend!F7)+_xlpm.shift), _xlpm.shape)} -> 0 | J10: {=_xlfn.LET(_xlpm.shift, Backend!$K$31, _xlpm.shape, INDEX(Backend!7:7,COLUMN(Backend!G7)+_xlpm.shift), _xlpm.shape)} -> 0 | K10: {=_xlfn.LET(_xlpm.shift, Backend!$K$31, _xlpm.shape, INDEX(Backend!7:7,COLUMN(Backend!H7)+_xlpm.shift), _xlpm.shape)} -> 0 | L10: {=_xlfn.LET(_xlpm.shift, Backend!$K$31, _xlpm.shape, INDEX(Backend!7:7,COLUMN(Backend!I7)+_xlpm.shift), _xlpm.shape)} -> 0 | M10: {=_xlfn.LET(_xlpm.shift, Backend!$K$31, _xlpm.shape, INDEX(Backend!7:7,COLUMN(Backend!J7)+_xlpm.shift), _xlpm.shape)} -> 0 | N10: {=_xlfn.LET(_xlpm.shift, Backend!$K$31, _xlpm.shape, INDEX(Backend!7:7,COLUMN(Backend!K7)+_xlpm.shift), _xlpm.shape)} -> 0 | ... V10: {=_xlfn.LET(_xlpm.shift, Backend!$K$31, _xlpm.shape, INDEX(Backend!7:7,COLUMN(Backend!S7)+_xlpm.shift), _xlpm.shape)} -> 0
D11: {=_xlfn.LET(_xlpm.shift, Backend!$K$31, _xlpm.shape, INDEX(Backend!8:8,COLUMN(Backend!A8)+_xlpm.shift), IF(Backend!$K$31=-1, 0, _xlpm.shape))} -> 0 | E11: {=_xlfn.LET(_xlpm.shift, Backend!$K$31, _xlpm.shape, INDEX(Backend!8:8,COLUMN(Backend!B8)+_xlpm.shift), IF($AA$19=-1, 0, _xlpm.shape))} -> 0 | F11: {=_xlfn.LET(_xlpm.shift, Backend!$K$31, _xlpm.up, Backend!K35, _xlpm.shape, IF(_xlpm.up=8, IF(AND(_xlpm.up=8, INDEX(Backend!8:8,COLUMN(Backend!C8)+_xlpm.shift)=1), 5, " ∎"), INDEX(Backend!8:8,COLUMN(Backend!C8)+_xlpm.shift)), _xlpm.shape)} -> 0 | G11: {=_xlfn.LET(_xlpm.shift, Backend!$K$31, _xlpm.shape, INDEX(Backend!8:8,COLUMN(Backend!D8)+_xlpm.shift), _xlpm.shape)} -> 0 | H11: {=_xlfn.LET(_xlpm.shift, Backend!$K$31, _xlpm.shape, INDEX(Backend!8:8,COLUMN(Backend!E8)+_xlpm.shift), _xlpm.shape)} -> 0 | I11: {=_xlfn.LET(_xlpm.shift, Backend!$K$31, _xlpm.shape, INDEX(Backend!8:8,COLUMN(Backend!F8)+_xlpm.shift), _xlpm.shape)} -> 0 | J11: {=_xlfn.LET(_xlpm.shift, Backend!$K$31, _xlpm.shape, INDEX(Backend!8:8,COLUMN(Backend!G8)+_xlpm.shift), _xlpm.shape)} -> 0 | K11: {=_xlfn.LET(_xlpm.shift, Backend!$K$31, _xlpm.shape, INDEX(Backend!8:8,COLUMN(Backend!H8)+_xlpm.shift), _xlpm.shape)} -> 0 | L11: {=_xlfn.LET(_xlpm.shift, Backend!$K$31, _xlpm.shape, INDEX(Backend!8:8,COLUMN(Backend!I8)+_xlpm.shift), _xlpm.shape)} -> 0 | M11: {=_xlfn.LET(_xlpm.shift, Backend!$K$31, _xlpm.shape, INDEX(Backend!8:8,COLUMN(Backend!J8)+_xlpm.shift), _xlpm.shape)} -> 0 | N11: {=_xlfn.LET(_xlpm.shift, Backend!$K$31, _xlpm.shape, INDEX(Backend!8:8,COLUMN(Backend!K8)+_xlpm.shift), _xlpm.shape)} -> 0 | ... V11: {=_xlfn.LET(_xlpm.shift, Backend!$K$31, _xlpm.shape, INDEX(Backend!8:8,COLUMN(Backend!S8)+_xlpm.shift), _xlpm.shape)} -> 1
D12: {=_xlfn.LET(_xlpm.shift, Backend!$K$31, _xlpm.shape, INDEX(Backend!9:9,COLUMN(Backend!A9)+_xlpm.shift), IF(Backend!$K$31=-1, 0, _xlpm.shape))} -> 0 | E12: {=_xlfn.LET(_xlpm.shift, Backend!$K$31, _xlpm.shape, INDEX(Backend!9:9,COLUMN(Backend!B9)+_xlpm.shift), IF($AA$19=-1, 0, _xlpm.shape))} -> 0 | F12: {=_xlfn.LET(_xlpm.shift, Backend!$K$31, _xlpm.up, Backend!K35, _xlpm.shape, IF(_xlpm.up=7, IF(AND(_xlpm.up=7, INDEX(Backend!9:9,COLUMN(Backend!C9)+_xlpm.shift)=1), 5, " ∎"), INDEX(Backend!9:9,COLUMN(Backend!C9)+_xlpm.shift)), _xlpm.shape)} -> ∎ | G12: {=_xlfn.LET(_xlpm.shift, Backend!$K$31, _xlpm.shape, INDEX(Backend!9:9,COLUMN(Backend!D9)+_xlpm.shift), _xlpm.shape)} -> 0 | H12: {=_xlfn.LET(_xlpm.shift, Backend!$K$31, _xlpm.shape, INDEX(Backend!9:9,COLUMN(Backend!E9)+_xlpm.shift), _xlpm.shape)} -> 0 | I12: {=_xlfn.LET(_xlpm.shift, Backend!$K$31, _xlpm.shape, INDEX(Backend!9:9,COLUMN(Backend!F9)+_xlpm.shift), _xlpm.shape)} -> 0 | J12: {=_xlfn.LET(_xlpm.shift, Backend!$K$31, _xlpm.shape, INDEX(Backend!9:9,COLUMN(Backend!G9)+_xlpm.shift), _xlpm.shape)} -> 0 | K12: {=_xlfn.LET(_xlpm.shift, Backend!$K$31, _xlpm.shape, INDEX(Backend!9:9,COLUMN(Backend!H9)+_xlpm.shift), _xlpm.shape)} -> 0 | L12: {=_xlfn.LET(_xlpm.shift, Backend!$K$31, _xlpm.shape, INDEX(Backend!9:9,COLUMN(Backend!I9)+_xlpm.shift), _xlpm.shape)} -> 0 | M12: {=_xlfn.LET(_xlpm.shift, Backend!$K$31, _xlpm.shape, INDEX(Backend!9:9,COLUMN(Backend!J9)+_xlpm.shift), _xlpm.shape)} -> 0 | N12: {=_xlfn.LET(_xlpm.shift, Backend!$K$31, _xlpm.shape, INDEX(Backend!9:9,COLUMN(Backend!K9)+_xlpm.shift), _xlpm.shape)} -> 0 | ... V12: {=_xlfn.LET(_xlpm.shift, Backend!$K$31, _xlpm.shape, INDEX(Backend!9:9,COLUMN(Backend!S9)+_xlpm.shift), _xlpm.shape)} -> 1
D13: {=_xlfn.LET(_xlpm.shift, Backend!$K$31, _xlpm.shape, INDEX(Backend!10:10,COLUMN(Backend!A10)+_xlpm.shift), IF(Backend!$K$31=-1, 0, _xlpm.shape))} -> 0 | E13: {=_xlfn.LET(_xlpm.shift, Backend!$K$31, _xlpm.shape, INDEX(Backend!10:10,COLUMN(Backend!B10)+_xlpm.shift), IF($AA$19=-1, 0, _xlpm.shape))} -> 0 | F13: {=_xlfn.LET(_xlpm.shift, Backend!$K$31, _xlpm.up, Backend!K35, _xlpm.shape, IF(_xlpm.up=6, IF(AND(_xlpm.up=6, INDEX(Backend!10:10,COLUMN(Backend!C10)+_xlpm.shift)=1), 5," ∎"), INDEX(Backend!10:10,COLUMN(Backend!C10)+_xlpm.shift)), _xlpm.shape)} -> 0 | G13: {=_xlfn.LET(_xlpm.shift, Backend!$K$31, _xlpm.shape, INDEX(Backend!10:10,COLUMN(Backend!D10)+_xlpm.shift), _xlpm.shape)} -> 0 | H13: {=_xlfn.LET(_xlpm.shift, Backend!$K$31, _xlpm.shape, INDEX(Backend!10:10,COLUMN(Backend!E10)+_xlpm.shift), _xlpm.shape)} -> 0 | I13: {=_xlfn.LET(_xlpm.shift, Backend!$K$31, _xlpm.shape, INDEX(Backend!10:10,COLUMN(Backend!F10)+_xlpm.shift), _xlpm.shape)} -> 0 | J13: {=_xlfn.LET(_xlpm.shift, Backend!$K$31, _xlpm.shape, INDEX(Backend!10:10,COLUMN(Backend!G10)+_xlpm.shift), _xlpm.shape)} -> 0 | K13: {=_xlfn.LET(_xlpm.shift, Backend!$K$31, _xlpm.shape, INDEX(Backend!10:10,COLUMN(Backend!H10)+_xlpm.shift), _xlpm.shape)} -> 0 | L13: {=_xlfn.LET(_xlpm.shift, Backend!$K$31, _xlpm.shape, INDEX(Backend!10:10,COLUMN(Backend!I10)+_xlpm.shift), _xlpm.shape)} -> 0 | M13: {=_xlfn.LET(_xlpm.shift, Backend!$K$31, _xlpm.shape, INDEX(Backend!10:10,COLUMN(Backend!J10)+_xlpm.shift), _xlpm.shape)} -> 0 | N13: {=_xlfn.LET(_xlpm.shift, Backend!$K$31, _xlpm.shape, INDEX(Backend!10:10,COLUMN(Backend!K10)+_xlpm.shift), _xlpm.shape)} -> 0 | ... V13: {=_xlfn.LET(_xlpm.shift, Backend!$K$31, _xlpm.shape, INDEX(Backend!10:10,COLUMN(Backend!S10)+_xlpm.shift), _xlpm.shape)} -> 1
D14: {=_xlfn.LET(_xlpm.shift, Backend!$K$31, _xlpm.shape, INDEX(Backend!11:11,COLUMN(Backend!A11)+_xlpm.shift), IF(Backend!$K$31=-1, 0, _xlpm.shape))} -> 0 | E14: {=_xlfn.LET(_xlpm.shift, Backend!$K$31, _xlpm.shape, INDEX(Backend!11:11,COLUMN(Backend!B11)+_xlpm.shift), IF($AA$19=-1, 0, _xlpm.shape))} -> 0 | F14: {=_xlfn.LET(_xlpm.shift, Backend!$K$31, _xlpm.up, Backend!K35, _xlpm.shape, IF(_xlpm.up=5, IF(AND(_xlpm.up=5, INDEX(Backend!11:11,COLUMN(Backend!C11)+_xlpm.shift)=1), 5, " ∎"), INDEX(Backend!11:11,COLUMN(Backend!C11)+_xlpm.shift)), _xlpm.shape)} -> 0 | G14: {=_xlfn.LET(_xlpm.shift, Backend!$K$31, _xlpm.shape, INDEX(Backend!11:11,COLUMN(Backend!D11)+_xlpm.shift), _xlpm.shape)} -> 0 | H14: {=_xlfn.LET(_xlpm.shift, Backend!$K$31, _xlpm.shape, INDEX(Backend!11:11,COLUMN(Backend!E11)+_xlpm.shift), _xlpm.shape)} -> 0 | I14: {=_xlfn.LET(_xlpm.shift, Backend!$K$31, _xlpm.shape, INDEX(Backend!11:11,COLUMN(Backend!F11)+_xlpm.shift), _xlpm.shape)} -> 0 | J14: {=_xlfn.LET(_xlpm.shift, Backend!$K$31, _xlpm.shape, INDEX(Backend!11:11,COLUMN(Backend!G11)+_xlpm.shift), _xlpm.shape)} -> 0 | K14: {=_xlfn.LET(_xlpm.shift, Backend!$K$31, _xlpm.shape, INDEX(Backend!11:11,COLUMN(Backend!H11)+_xlpm.shift), _xlpm.shape)} -> 0 | L14: {=_xlfn.LET(_xlpm.shift, Backend!$K$31, _xlpm.shape, INDEX(Backend!11:11,COLUMN(Backend!I11)+_xlpm.shift), _xlpm.shape)} -> 0 | M14: {=_xlfn.LET(_xlpm.shift, Backend!$K$31, _xlpm.shape, INDEX(Backend!11:11,COLUMN(Backend!J11)+_xlpm.shift), _xlpm.shape)} -> 1 | N14: {=_xlfn.LET(_xlpm.shift, Backend!$K$31, _xlpm.shape, INDEX(Backend!11:11,COLUMN(Backend!K11)+_xlpm.shift), _xlpm.shape)} -> 1 | ... V14: {=_xlfn.LET(_xlpm.shift, Backend!$K$31, _xlpm.shape, INDEX(Backend!11:11,COLUMN(Backend!S11)+_xlpm.shift), _xlpm.shape)} -> 1
D15: {=_xlfn.LET(_xlpm.shift, Backend!$K$31, _xlpm.shape, INDEX(Backend!12:12,COLUMN(Backend!A12)+_xlpm.shift), IF(Backend!$K$31=-1, 0, _xlpm.shape))} -> 0 | E15: {=_xlfn.LET(_xlpm.shift, Backend!$K$31, _xlpm.shape, INDEX(Backend!12:12,COLUMN(Backend!B12)+_xlpm.shift), IF($AA$19=-1, 0, _xlpm.shape))} -> 0 | F15: {=_xlfn.LET(_xlpm.shift, Backend!$K$31, _xlpm.up, Backend!K35, _xlpm.shape, IF(_xlpm.up=4, IF(AND(_xlpm.up=4, INDEX(Backend!12:12,COLUMN(Backend!C12)+_xlpm.shift)=1), 5, " ∎"), INDEX(Backend!12:12,COLUMN(Backend!C12)+_xlpm.shift)), _xlpm.shape)} -> 0 | G15: {=_xlfn.LET(_xlpm.shift, Backend!$K$31, _xlpm.shape, INDEX(Backend!12:12,COLUMN(Backend!D12)+_xlpm.shift), _xlpm.shape)} -> 0 | H15: {=_xlfn.LET(_xlpm.shift, Backend!$K$31, _xlpm.shape, INDEX(Backend!12:12,COLUMN(Backend!E12)+_xlpm.shift), _xlpm.shape)} -> 0 | I15: {=_xlfn.LET(_xlpm.shift, Backend!$K$31, _xlpm.shape, INDEX(Backend!12:12,COLUMN(Backend!F12)+_xlpm.shift), _xlpm.shape)} -> 1 | J15: {=_xlfn.LET(_xlpm.shift, Backend!$K$31, _xlpm.shape, INDEX(Backend!12:12,COLUMN(Backend!G12)+_xlpm.shift), _xlpm.shape)} -> 1 | K15: {=_xlfn.LET(_xlpm.shift, Backend!$K$31, _xlpm.shape, INDEX(Backend!12:12,COLUMN(Backend!H12)+_xlpm.shift), _xlpm.shape)} -> 0 | L15: {=_xlfn.LET(_xlpm.shift, Backend!$K$31, _xlpm.shape, INDEX(Backend!12:12,COLUMN(Backend!I12)+_xlpm.shift), _xlpm.shape)} -> 0 | M15: {=_xlfn.LET(_xlpm.shift, Backend!$K$31, _xlpm.shape, INDEX(Backend!12:12,COLUMN(Backend!J12)+_xlpm.shift), _xlpm.shape)} -> 1 | N15: {=_xlfn.LET(_xlpm.shift, Backend!$K$31, _xlpm.shape, INDEX(Backend!12:12,COLUMN(Backend!K12)+_xlpm.shift), _xlpm.shape)} -> 1 | ... V15: {=_xlfn.LET(_xlpm.shift, Backend!$K$31, _xlpm.shape, INDEX(Backend!12:12,COLUMN(Backend!S12)+_xlpm.shift), _xlpm.shape)} -> 1
D16: {=_xlfn.LET(_xlpm.shift, Backend!$K$31, _xlpm.shape, INDEX(Backend!13:13,COLUMN(Backend!A13)+_xlpm.shift), IF(Backend!$K$31=-1, 0, _xlpm.shape))} -> 0 | E16: {=_xlfn.LET(_xlpm.shift, Backend!$K$31, _xlpm.shape, INDEX(Backend!13:13,COLUMN(Backend!B13)+_xlpm.shift), IF($AA$19=-1, 0, _xlpm.shape))} -> 0 | F16: {=_xlfn.LET(_xlpm.shift, Backend!$K$31, _xlpm.up, Backend!K35, _xlpm.shape, IF(_xlpm.up=3, IF(AND(_xlpm.up=3, INDEX(Backend!13:13,COLUMN(Backend!C13)+_xlpm.shift)=1), 5," ∎"), INDEX(Backend!13:13,COLUMN(Backend!C13)+_xlpm.shift)), _xlpm.shape)} -> 0 | G16: {=_xlfn.LET(_xlpm.shift, Backend!$K$31, _xlpm.shape, INDEX(Backend!13:13,COLUMN(Backend!D13)+_xlpm.shift), _xlpm.shape)} -> 0 | H16: {=_xlfn.LET(_xlpm.shift, Backend!$K$31, _xlpm.shape, INDEX(Backend!13:13,COLUMN(Backend!E13)+_xlpm.shift), _xlpm.shape)} -> 0 | I16: {=_xlfn.LET(_xlpm.shift, Backend!$K$31, _xlpm.shape, INDEX(Backend!13:13,COLUMN(Backend!F13)+_xlpm.shift), _xlpm.shape)} -> 1 | J16: {=_xlfn.LET(_xlpm.shift, Backend!$K$31, _xlpm.shape, INDEX(Backend!13:13,COLUMN(Backend!G13)+_xlpm.shift), _xlpm.shape)} -> 1 | K16: {=_xlfn.LET(_xlpm.shift, Backend!$K$31, _xlpm.shape, INDEX(Backend!13:13,COLUMN(Backend!H13)+_xlpm.shift), _xlpm.shape)} -> 0 | L16: {=_xlfn.LET(_xlpm.shift, Backend!$K$31, _xlpm.shape, INDEX(Backend!13:13,COLUMN(Backend!I13)+_xlpm.shift), _xlpm.shape)} -> 0 | M16: {=_xlfn.LET(_xlpm.shift, Backend!$K$31, _xlpm.shape, INDEX(Backend!13:13,COLUMN(Backend!J13)+_xlpm.shift), _xlpm.shape)} -> 1 | N16: {=_xlfn.LET(_xlpm.shift, Backend!$K$31, _xlpm.shape, INDEX(Backend!13:13,COLUMN(Backend!K13)+_xlpm.shift), _xlpm.shape)} -> 1 | ... V16: {=_xlfn.LET(_xlpm.shift, Backend!$K$31, _xlpm.shape, INDEX(Backend!13:13,COLUMN(Backend!S13)+_xlpm.shift), _xlpm.shape)} -> 1
D17: {=_xlfn.LET(_xlpm.shift, Backend!$K$31, _xlpm.shape, INDEX(Backend!14:14,COLUMN(Backend!A14)+_xlpm.shift), IF(Backend!$K$31=-1, 0, _xlpm.shape))} -> 0 | E17: {=_xlfn.LET(_xlpm.shift, Backend!$K$31, _xlpm.shape, INDEX(Backend!14:14,COLUMN(Backend!B14)+_xlpm.shift), IF($AA$19=-1, 0, _xlpm.shape))} -> 0 | F17: {=_xlfn.LET(_xlpm.shift, Backend!$K$31, _xlpm.up, Backend!K35, _xlpm.shape, IF(_xlpm.up=2, IF(AND(_xlpm.up=2, INDEX(Backend!14:14,COLUMN(Backend!C14)+_xlpm.shift)=1), 5, " ∎"), INDEX(Backend!14:14,COLUMN(Backend!C14)+_xlpm.shift)), _xlpm.shape)} -> 0 | G17: {=_xlfn.LET(_xlpm.shift, Backend!$K$31, _xlpm.shape, INDEX(Backend!14:14,COLUMN(Backend!D14)+_xlpm.shift), _xlpm.shape)} -> 0 | H17: {=_xlfn.LET(_xlpm.shift, Backend!$K$31, _xlpm.shape, INDEX(Backend!14:14,COLUMN(Backend!E14)+_xlpm.shift), _xlpm.shape)} -> 0 | I17: {=_xlfn.LET(_xlpm.shift, Backend!$K$31, _xlpm.shape, INDEX(Backend!14:14,COLUMN(Backend!F14)+_xlpm.shift), _xlpm.shape)} -> 1 | J17: {=_xlfn.LET(_xlpm.shift, Backend!$K$31, _xlpm.shape, INDEX(Backend!14:14,COLUMN(Backend!G14)+_xlpm.shift), _xlpm.shape)} -> 1 | K17: {=_xlfn.LET(_xlpm.shift, Backend!$K$31, _xlpm.shape, INDEX(Backend!14:14,COLUMN(Backend!H14)+_xlpm.shift), _xlpm.shape)} -> 0 | L17: {=_xlfn.LET(_xlpm.shift, Backend!$K$31, _xlpm.shape, INDEX(Backend!14:14,COLUMN(Backend!I14)+_xlpm.shift), _xlpm.shape)} -> 0 | M17: {=_xlfn.LET(_xlpm.shift, Backend!$K$31, _xlpm.shape, INDEX(Backend!14:14,COLUMN(Backend!J14)+_xlpm.shift), _xlpm.shape)} -> 1 | N17: {=_xlfn.LET(_xlpm.shift, Backend!$K$31, _xlpm.shape, INDEX(Backend!14:14,COLUMN(Backend!K14)+_xlpm.shift), _xlpm.shape)} -> 1 | ... V17: {=_xlfn.LET(_xlpm.shift, Backend!$K$31, _xlpm.shape, INDEX(Backend!14:14,COLUMN(Backend!S14)+_xlpm.shift), _xlpm.shape)} -> 1
D18: {=_xlfn.LET(_xlpm.shift, Backend!$K$31, _xlpm.shape, INDEX(Backend!15:15,COLUMN(Backend!A15)+_xlpm.shift), IF(Backend!$K$31=-1, 0, _xlpm.shape))} -> 0 | E18: {=_xlfn.LET(_xlpm.shift, Backend!$K$31, _xlpm.shape, INDEX(Backend!15:15,COLUMN(Backend!B15)+_xlpm.shift), IF($AA$19=-1, 0, _xlpm.shape))} -> 0 | F18: {=_xlfn.LET(_xlpm.shift, Backend!$K$31, _xlpm.up, Backend!K35, _xlpm.shape, IF(_xlpm.up=1, IF(AND(_xlpm.up=1, INDEX(Backend!15:15,COLUMN(Backend!C15)+_xlpm.shift)=1), 5, " ∎"), INDEX(Backend!15:15,COLUMN(Backend!C15)+_xlpm.shift)), _xlpm.shape)} -> 0 | G18: {=_xlfn.LET(_xlpm.shift, Backend!$K$31, _xlpm.shape, INDEX(Backend!15:15,COLUMN(Backend!D15)+_xlpm.shift), _xlpm.shape)} -> 0 | H18: {=_xlfn.LET(_xlpm.shift, Backend!$K$31, _xlpm.shape, INDEX(Backend!15:15,COLUMN(Backend!E15)+_xlpm.shift), _xlpm.shape)} -> 0 | I18: {=_xlfn.LET(_xlpm.shift, Backend!$K$31, _xlpm.shape, INDEX(Backend!15:15,COLUMN(Backend!F15)+_xlpm.shift), _xlpm.shape)} -> 1 | J18: {=_xlfn.LET(_xlpm.shift, Backend!$K$31, _xlpm.shape, INDEX(Backend!15:15,COLUMN(Backend!G15)+_xlpm.shift), _xlpm.shape)} -> 1 | K18: {=_xlfn.LET(_xlpm.shift, Backend!$K$31, _xlpm.shape, INDEX(Backend!15:15,COLUMN(Backend!H15)+_xlpm.shift), _xlpm.shape)} -> 0 | L18: {=_xlfn.LET(_xlpm.shift, Backend!$K$31, _xlpm.shape, INDEX(Backend!15:15,COLUMN(Backend!I15)+_xlpm.shift), _xlpm.shape)} -> 0 | M18: {=_xlfn.LET(_xlpm.shift, Backend!$K$31, _xlpm.shape, INDEX(Backend!15:15,COLUMN(Backend!J15)+_xlpm.shift), _xlpm.shape)} -> 1 | N18: {=_xlfn.LET(_xlpm.shift, Backend!$K$31, _xlpm.shape, INDEX(Backend!15:15,COLUMN(Backend!K15)+_xlpm.shift), _xlpm.shape)} -> 1 | ... V18: {=_xlfn.LET(_xlpm.shift, Backend!$K$31, _xlpm.shape, INDEX(Backend!15:15,COLUMN(Backend!S15)+_xlpm.shift), _xlpm.shape)} -> 1
D19: {=_xlfn.LET(_xlpm.shift, Backend!$K$31, _xlpm.shape, INDEX(Backend!16:16,COLUMN(Backend!A16)+_xlpm.shift), IF(Backend!$K$31=-1, 0, _xlpm.shape))} -> 0 | E19: {=_xlfn.LET(_xlpm.shift, Backend!$K$31, _xlpm.shape, INDEX(Backend!16:16,COLUMN(Backend!B16)+_xlpm.shift), IF($AA$19=-1, 0, _xlpm.shape))} -> 0 | F19: {=_xlfn.LET(_xlpm.shift, Backend!$K$31, _xlpm.up, Backend!K35, _xlpm.shape, IF(_xlpm.up=0, IF(AND(_xlpm.up=0, INDEX(Backend!16:16,COLUMN(Backend!C16)+_xlpm.shift)=1), 5, " ∎"), INDEX(Backend!16:16,COLUMN(Backend!C16)+_xlpm.shift)), _xlpm.shape)} -> 0 | G19: {=_xlfn.LET(_xlpm.shift, Backend!$K$31, _xlpm.shape, INDEX(Backend!16:16,COLUMN(Backend!D16)+_xlpm.shift), _xlpm.shape)} -> 0 | H19: {=_xlfn.LET(_xlpm.shift, Backend!$K$31, _xlpm.shape, INDEX(Backend!16:16,COLUMN(Backend!E16)+_xlpm.shift), _xlpm.shape)} -> 0 | I19: {=_xlfn.LET(_xlpm.shift, Backend!$K$31, _xlpm.shape, INDEX(Backend!16:16,COLUMN(Backend!F16)+_xlpm.shift), _xlpm.shape)} -> 1 | J19: {=_xlfn.LET(_xlpm.shift, Backend!$K$31, _xlpm.shape, INDEX(Backend!16:16,COLUMN(Backend!G16)+_xlpm.shift), _xlpm.shape)} -> 1 | K19: {=_xlfn.LET(_xlpm.shift, Backend!$K$31, _xlpm.shape, INDEX(Backend!16:16,COLUMN(Backend!H16)+_xlpm.shift), _xlpm.shape)} -> 0 | L19: {=_xlfn.LET(_xlpm.shift, Backend!$K$31, _xlpm.shape, INDEX(Backend!16:16,COLUMN(Backend!I16)+_xlpm.shift), _xlpm.shape)} -> 0 | M19: {=_xlfn.LET(_xlpm.shift, Backend!$K$31, _xlpm.shape, INDEX(Backend!16:16,COLUMN(Backend!J16)+_xlpm.shift), _xlpm.shape)} -> 1 | N19: {=_xlfn.LET(_xlpm.shift, Backend!$K$31, _xlpm.shape, INDEX(Backend!16:16,COLUMN(Backend!K16)+_xlpm.shift), _xlpm.shape)} -> 1 | ... V19: {=_xlfn.LET(_xlpm.shift, Backend!$K$31, _xlpm.shape, INDEX(Backend!16:16,COLUMN(Backend!S16)+_xlpm.shift), _xlpm.shape)} -> 1
D20: FALSE | E20: FALSE | F20: FALSE | G20: FALSE | H20: FALSE | I20: FALSE | J20: FALSE | K20: TRUE | L20: FALSE | M20: FALSE | N20: TRUE | O20: TRUE | P20: FALSE | Q20: =IF(V20=FALSE, " Click to start", "Click to restart") -> Click to restart | V20: TRUE
B21: Back
O25: %

Sheet 2048
A1: 2048
B2: 0 | C2: 0 | D2: 2 | E2: 0
B3: 0 | C3: 0 | D3: 0 | E3: 0 | H3: 0 | I3: 4132
B4: 0 | C4: 0 | D4: 0 | E4: 0
B5: 2 | C5: 0 | D5: 0 | E5: 0
H6: Playing
B8: Move in Direction: | D8: Select
A9: Back

Sheet Backend
A1: {=_xlfn.SEQUENCE(1,300)} -> 1 | B1: 2 | C1: 3 | D1: 4 | E1: 5 | F1: 6 | G1: 7 | H1: 8 | I1: 9 | J1: 10 | K1: 11 | L1: 12 | M1: 13 | N1: 14 | O1: 15 | P1: 16 | Q1: 17 | R1: 18 | S1: 19 | T1: 20 | U1: 21 | V1: 22 | W1: 23 | X1: 24 | Y1: 25 | Z1: 26 | AA1: 27 | AB1: 28 | AC1: 29 | AD1: 30 | AE1: 31 | AF1: 32 | AG1: 33 | AH1: 34 | AI1: 35 | AJ1: 36 | AK1: 37 | AL1: 38 | AM1: 39 | AN1: 40 | AO1: 41 | AP1: 42 | AQ1: 43 | AR1: 44 | AS1: 45 | AT1: 46 | AU1: 47 | AV1: 48 | AW1: 49 | AX1: 50 | AY1: 51 | AZ1: 52 | BA1: 53 | BB1: 54 | BC1: 55 | BD1: 56 | BE1: 57 | BF1: 58 | BG1: 59 | BH1: 60 | BI1: 61 | BJ1: 62 | BK1: 63 | BL1: 64 | BM1: 65 | BN1: 66 | BO1: 67 | BP1: 68 | BQ1: 69 | BR1: 70 | BS1: 71 | BT1: 72 | BU1: 73 | BV1: 74 | BW1: 75 | BX1: 76 | BY1: 77 | BZ1: 78 | CA1: 79 | CB1: 80 | CC1: 81 | CD1: 82 | CE1: 83 | CF1: 84 | CG1: 85 | CH1: 86 | CI1: 87 | CJ1: 88 | CK1: 89 | CL1: 90 | CM1: 91 | CN1: 92 | CO1: 93 | CP1: 94 | CQ1: 95 | CR1: 96 | CS1: 97 | CT1: 98 | CU1: 99 | CV1: 100 | CW1: 101 | CX1: 102 | CY1: 103 | CZ1: 104 | DA1: 105 | DB1: 106 | DC1: 107 | DD1: 108 | DE1: 109 | DF1: 110 | DG1: 111 | DH1: 112 | DI1: 113 | DJ1: 114 | DK1: 115 | DL1: 116 | DM1: 117 | DN1: 118 | DO1: 119 | DP1: 120 | DQ1: 121 | DR1: 122 | DS1: 123 | DT1: 124 | DU1: 125 | DV1: 126 | DW1: 127 | DX1: 128 | DY1: 129 | DZ1: 130 | EA1: 131 | EB1: 132 | EC1: 133 | ED1: 134 | EE1: 135 | EF1: 136 | EG1: 137 | EH1: 138 | EI1: 139 | EJ1: 140 | EK1: 141 | EL1: 142 | EM1: 143 | EN1: 144 | EO1: 145 | EP1: 146 | EQ1: 147 | ER1: 148 | ES1: 149 | ET1: 150 | EU1: 151 | EV1: 152 | EW1: 153 | EX1: 154 | EY1: 155 | EZ1: 156 | FA1: 157 | FB1: 158 | FC1: 159 | FD1: 160 | FE1: 161 | FF1: 162 | FG1: 163 | FH1: 164 | FI1: 165 | FJ1: 166 | FK1: 167 | FL1: 168 | FM1: 169 | FN1: 170 | FO1: 171 | FP1: 172 | FQ1: 173 | FR1: 174 | FS1: 175 | FT1: 176 | FU1: 177 | FV1: 178 | FW1: 179 | FX1: 180 | FY1: 181 | FZ1: 182 | GA1: 183 | GB1: 184 | GC1: 185 | GD1: 186 | GE1: 187 | GF1: 188 | GG1: 189 | GH1: 190 | GI1: 191 | GJ1: 192 | GK1: 193 | GL1: 194 | GM1: 195 | GN1: 196 | GO1: 197 | GP1: 198 | GQ1: 199 | GR1: 200 | GS1: 201 | GT1: 202 | GU1: 203 | GV1: 204 | GW1: 205 | GX1: 206 | GY1: 207 | GZ1: 208 | HA1: 209 | HB1: 210 | HC1: 211 | HD1: 212 | HE1: 213 | HF1: 214 | HG1: 215 | HH1: 216 | HI1: 217 | HJ1: 218 | HK1: 219 | HL1: 220 | HM1: 221 | HN1: 222 | HO1: 223 | HP1: 224 | HQ1: 225 | HR1: 226 | HS1: 227 | HT1: 228 | HU1: 229 | HV1: 230 | HW1: 231 | HX1: 232 | HY1: 233 | HZ1: 234 | IA1: 235 | IB1: 236 | IC1: 237 | ID1: 238 | IE1: 239 | IF1: 240 | IG1: 241 | IH1: 242 | II1: 243 | IJ1: 244 | IK1: 245 | IL1: 246 | IM1: 247 | IN1: 248 | IO1: 249 | IP1: 250 | IQ1: 251 | IR1: 252 | IS1: 253 | IT1: 254 | IU1: 255 | IV1: 256 | IW1: 257 | IX1: 258 | IY1: 259 | IZ1: 260 | JA1: 261 | JB1: 262 | JC1: 263 | JD1: 264 | JE1: 265 | JF1: 266 | JG1: 267 | JH1: 268 | JI1: 269 | JJ1: 270 | JK1: 271 | JL1: 272 | JM1: 273 | JN1: 274 | JO1: 275 | JP1: 276 | JQ1: 277 | JR1: 278 | JS1: 279 | JT1: 280 | JU1: 281 | JV1: 282 | JW1: 283 | JX1: 284 | JY1: 285 | JZ1: 286 | KA1: 287 | KB1: 288 | KC1: 289 | KD1: 290 | KE1: 291 | KF1: 292 | KG1: 293 | KH1: 294 | KI1: 295 | KJ1: 296 | KK1: 297 | KL1: 298 | KM1: 299 | KN1: 300
A2: 0 | B2: 0 | C2: {=IF(MOD(COLUMN()-1,4)<2, IF(AND(ROW()>=INDEX($A$22:$KN$22, COLUMN()), ROW()<INDEX($A$22:$KN$22, COLUMN())+3), 0, 1), 0)} -> 0 | D2: {=IF(MOD(COLUMN()-1,4)<2, IF(AND(ROW()>=INDEX($A$22:$KN$22, COLUMN()), ROW()<INDEX($A$22:$KN$22, COLUMN())+3), 0, 1), 0)} -> 0 | E2: {=IF(MOD(COLUMN()-1,4)<2, IF(AND(ROW()>=INDEX($A$22:$KN$22, COLUMN()), ROW()<INDEX($A$22:$KN$22, COLUMN())+5), 0, 1), 0)} -> 1 | F2: {=IF(MOD(COLUMN()-1,4)<2, IF(AND(ROW()>=INDEX($A$22:$KN$22, COLUMN()), ROW()<INDEX($A$22:$KN$22, COLUMN())+5), 0, 1), 0)} -> 1 | G2: {=IF(MOD(COLUMN()-1,4)<2, IF(AND(ROW()>=INDEX($A$22:$KN$22, COLUMN()), ROW()<INDEX($A$22:$KN$22, COLUMN())+5), 0, 1), 0)} -> 0 | H2: {=IF(MOD(COLUMN()-1,4)<2, IF(AND(ROW()>=INDEX($A$22:$KN$22, COLUMN()), ROW()<INDEX($A$22:$KN$22, COLUMN())+5), 0, 1), 0)} -> 0 | I2: {=IF(MOD(COLUMN()-1,4)<2, IF(AND(ROW()>=INDEX($A$22:$KN$22, COLUMN()), ROW()<INDEX($A$22:$KN$22, COLUMN())+5), 0, 1), 0)} -> 1 | J2: {=IF(MOD(COLUMN()-1,4)<2, IF(AND(ROW()>=INDEX($A$22:$KN$22, COLUMN()), ROW()<INDEX($A$22:$KN$22, COLUMN())+5), 0, 1), 0)} -> 1 | K2: {=IF(MOD(COLUMN()-1,4)<2, IF(AND(ROW()>=INDEX($A$22:$KN$22, COLUMN()), ROW()<INDEX($A$22:$KN$22, COLUMN())+5), 0, 1), 0)} -> 0 | L2: {=IF(MOD(COLUMN()-1,4)<2, IF(AND(ROW()>=INDEX($A$22:$KN$22, COLUMN()), ROW()<INDEX($A$22:$KN$22, COLUMN())+5), 0, 1), 0)} -> 0 | ... N2: {=IF(MOD(COLUMN()-1,4)<2, IF(AND(ROW()>=INDEX($A$22:$KN$22, COLUMN()), ROW()<INDEX($A$22:$KN$22, COLUMN())+5), 0, 1), 0)} -> 1 | O2: {=IF(MOD(COLUMN()-1,4)<2, IF(AND(ROW()>=INDEX($A$22:$KN$22, COLUMN()), ROW()<INDEX($A$22:$KN$22, COLUMN())+3), 0, 1), 0)} -> 0 | P2: {=IF(MOD(COLUMN()-1,4)<2, IF(AND(ROW()>=INDEX($A$22:$KN$22, COLUMN()), ROW()<INDEX($A$22:$KN$22, COLUMN())+3), 0, 1), 0)} -> 0 | Q2: {=IF(MOD(COLUMN()-1,4)<2, IF(AND(ROW()>=INDEX($A$22:$KN$22, COLUMN()), ROW()<INDEX($A$22:$KN$22, COLUMN())+4), 0, 1), 0)} -> 1 | R2: {=IF(MOD(COLUMN()-1,4)<2, IF(AND(ROW()>=INDEX($A$22:$KN$22, COLUMN()), ROW()<INDEX($A$22:$KN$22, COLUMN())+4), 0, 1), 0)} -> 1 | S2: {=IF(MOD(COLUMN()-1,4)<2, IF(AND(ROW()>=INDEX($A$22:$KN$22, COLUMN()), ROW()<INDEX($A$22:$KN$22, COLUMN())+4), 0, 1), 0)} -> 0 | T2: {=IF(MOD(COLUMN()-1,4)<2, IF(AND(ROW()>=INDEX($A$22:$KN$22, COLUMN()), ROW()<INDEX($A$22:$KN$22, COLUMN())+4), 0, 1), 0)} -> 0 | U2: {=IF(MOD(COLUMN()-1,4)<2, IF(AND(ROW()>=INDEX($A$22:$KN$22, COLUMN()), ROW()<INDEX($A$22:$KN$22, COLUMN())+4), 0, 1), 0)} -> 1 | V2: {=IF(MOD(COLUMN()-1,4)<2, IF(AND(ROW()>=INDEX($A$22:$KN$22, COLUMN()), ROW()<INDEX($A$22:$KN$22, COLUMN())+4), 0, 1), 0)} -> 1 | W2: {=IF(MOD(COLUMN()-1,4)<2, IF(AND(ROW()>=INDEX($A$22:$KN$22, COLUMN()), ROW()<INDEX($A$22:$KN$22, COLUMN())+4), 0, 1), 0)} -> 0 | X2: {=IF(MOD(COLUMN()-1,4)<2, IF(AND(ROW()>=INDEX($A$22:$KN$22, COLUMN()), ROW()<INDEX($A$22:$KN$22, COLUMN())+4), 0, 1), 0)} -> 0 | ... AL2: {=IF(MOD(COLUMN()-1,4)<2, IF(AND(ROW()>=INDEX($A$22:$KN$22, COLUMN()), ROW()<INDEX($A$22:$KN$22, COLUMN())+4), 0, 1), 0)} -> 1 | AM2: {=IF(MOD(COLUMN()-1,4)<2, IF(AND(ROW()>=INDEX($A$22:$KN$22, COLUMN()), ROW()<INDEX($A$22:$KN$22, COLUMN())+3), 0, 1), 0)} -> 0 | AN2: {=IF(MOD(COLUMN()-1,4)<2, IF(AND(ROW()>=INDEX($A$22:$KN$22, COLUMN()), ROW()<INDEX($A$22:$KN$22, COLUMN())+3), 0, 1), 0)} -> 0 | AO2: {=IF(MOD(COLUMN()-1,4)<2, IF(AND(ROW()>=INDEX($A$22:$KN$22, COLUMN()), ROW()<INDEX($A$22:$KN$22, COLUMN())+3), 0, 1), 0)} -> 1 | AP2: {=IF(MOD(COLUMN()-1,4)<2, IF(AND(ROW()>=INDEX($A$22:$KN$22, COLUMN()), ROW()<INDEX($A$22:$KN$22, COLUMN())+3), 0, 1), 0)} -> 1 | AQ2: {=IF(MOD(COLUMN()-1,4)<2, IF(AND(ROW()>=INDEX($A$22:$KN$22, COLUMN()), ROW()<INDEX($A$22:$KN$22, COLUMN())+3), 0, 1), 0)} -> 0 | AR2: {=IF(MOD(COLUMN()-1,4)<2, IF(AND(ROW()>=INDEX($A$22:$KN$22, COLUMN()), ROW()<INDEX($A$22:$KN$22, COLUMN())+3), 0, 1), 0)} -> 0 | AS2: {=IF(MOD(COLUMN()-1,4)<2, IF(AND(ROW()>=INDEX($A$22:$KN$22, COLUMN()), ROW()<INDEX($A$22:$KN$22, COLUMN())+3), 0, 1), 0)} -> 1 | AT2: {=IF(MOD(COLUMN()-1,4)<2, IF(AND(ROW()>=INDEX($A$22:$KN$22, COLUMN()), ROW()<INDEX($A$22:$KN$22, COLUMN())+3), 0, 1), 0)} -> 1 | ... BX2: {=IF(MOD(COLUMN()-1,4)<2, IF(AND(ROW()>=INDEX($A$22:$KN$22, COLUMN()), ROW()<INDEX($A$22:$KN$22, COLUMN())+3), 0, 1), 0)} -> 0 | BY2: {=IF(MOD(COLUMN()-1,4)<2, IF(AND(ROW()>=INDEX($A$22:$KN$22, COLUMN()), ROW()<INDEX($A$22:$KN$22, COLUMN())+2), 0, 1), 0)} -> 1 | BZ2: {=IF(MOD(COLUMN()-1,4)<2, IF(AND(ROW()>=INDEX($A$22:$KN$22, COLUMN()), ROW()<INDEX($A$22:$KN$22, COLUMN())+2), 0, 1), 0)} -> 1 | CA2: {=IF(MOD(COLUMN()-1,4)<2, IF(AND(ROW()>=INDEX($A$22:$KN$22, COLUMN()), ROW()<INDEX($A$22:$KN$22, COLUMN())+2), 0, 1), 0)} -> 0 | CB2: {=IF(MOD(COLUMN()-1,4)<2, IF(AND(ROW()>=INDEX($A$22:$KN$22, COLUMN()), ROW()<INDEX($A$22:$KN$22, COLUMN())+2), 0, 1), 0)} -> 0 | CC2: {=IF(MOD(COLUMN()-1,4)<2, IF(AND(ROW()>=INDEX($A$22:$KN$22, COLUMN()), ROW()<INDEX($A$22:$KN$22, COLUMN())+2), 0, 1), 0)} -> 1 | CD2: {=IF(MOD(COLUMN()-1,4)<2, IF(AND(ROW()>=INDEX($A$22:$KN$22, COLUMN()), ROW()<INDEX($A$22:$KN$22, COLUMN())+2), 0, 1), 0)} -> 1 | CE2: {=IF(MOD(COLUMN()-1,4)<2, IF(AND(ROW()>=INDEX($A$22:$KN$22, COLUMN()), ROW()<INDEX($A$22:$KN$22, COLUMN())+2), 0, 1), 0)} -> 0 | CF2: {=IF(MOD(COLUMN()-1,4)<2, IF(AND(ROW()>=INDEX($A$22:$KN$22, COLUMN()), ROW()<INDEX($A$22:$KN$22, COLUMN())+2), 0, 1), 0)} -> 0 | ... KN2: {=IF(MOD(COLUMN()-1,4)<2, IF(AND(ROW()>=INDEX($A$22:$KN$22, COLUMN()), ROW()<INDEX($A$22:$KN$22, COLUMN())+2), 0, 1), 0)} -> 0
A3: 0 | B3: 0 | C3: {=IF(MOD(COLUMN()-1,4)<2, IF(AND(ROW()>=INDEX($A$22:$KN$22, COLUMN()), ROW()<INDEX($A$22:$KN$22, COLUMN())+3), 0, 1), 0)} -> 0 | D3: {=IF(MOD(COLUMN()-1,4)<2, IF(AND(ROW()>=INDEX($A$22:$KN$22, COLUMN()), ROW()<INDEX($A$22:$KN$22, COLUMN())+3), 0, 1), 0)} -> 0 | E3: {=IF(MOD(COLUMN()-1,4)<2, IF(AND(ROW()>=INDEX($A$22:$KN$22, COLUMN()), ROW()<INDEX($A$22:$KN$22, COLUMN())+5), 0, 1), 0)} -> 1 | F3: {=IF(MOD(COLUMN()-1,4)<2, IF(AND(ROW()>=INDEX($A$22:$KN$22, COLUMN()), ROW()<INDEX($A$22:$KN$22, COLUMN())+5), 0, 1), 0)} -> 1 | G3: {=IF(MOD(COLUMN()-1,4)<2, IF(AND(ROW()>=INDEX($A$22:$KN$22, COLUMN()), ROW()<INDEX($A$22:$KN$22, COLUMN())+5), 0, 1), 0)} -> 0 | H3: {=IF(MOD(COLUMN()-1,4)<2, IF(AND(ROW()>=INDEX($A$22:$KN$22, COLUMN()), ROW()<INDEX($A$22:$KN$22, COLUMN())+5), 0, 1), 0)} -> 0 | I3: {=IF(MOD(COLUMN()-1,4)<2, IF(AND(ROW()>=INDEX($A$22:$KN$22, COLUMN()), ROW()<INDEX($A$22:$KN$22, COLUMN())+5), 0, 1), 0)} -> 1 | J3: {=IF(MOD(COLUMN()-1,4)<2, IF(AND(ROW()>=INDEX($A$22:$KN$22, COLUMN()), ROW()<INDEX($A$22:$KN$22, COLUMN())+5), 0, 1), 0)} -> 1 | K3: {=IF(MOD(COLUMN()-1,4)<2, IF(AND(ROW()>=INDEX($A$22:$KN$22, COLUMN()), ROW()<INDEX($A$22:$KN$22, COLUMN())+5), 0, 1), 0)} -> 0 | L3: {=IF(MOD(COLUMN()-1,4)<2, IF(AND(ROW()>=INDEX($A$22:$KN$22, COLUMN()), ROW()<INDEX($A$22:$KN$22, COLUMN())+5), 0, 1), 0)} -> 0 | ... N3: {=IF(MOD(COLUMN()-1,4)<2, IF(AND(ROW()>=INDEX($A$22:$KN$22, COLUMN()), ROW()<INDEX($A$22:$KN$22, COLUMN())+5), 0, 1), 0)} -> 1 | O3: {=IF(MOD(COLUMN()-1,4)<2, IF(AND(ROW()>=INDEX($A$22:$KN$22, COLUMN()), ROW()<INDEX($A$22:$KN$22, COLUMN())+3), 0, 1), 0)} -> 0 | P3: {=IF(MOD(COLUMN()-1,4)<2, IF(AND(ROW()>=INDEX($A$22:$KN$22, COLUMN()), ROW()<INDEX($A$22:$KN$22, COLUMN())+3), 0, 1), 0)} -> 0 | Q3: {=IF(MOD(COLUMN()-1,4)<2, IF(AND(ROW()>=INDEX($A$22:$KN$22, COLUMN()), ROW()<INDEX($A$22:$KN$22, COLUMN())+4), 0, 1), 0)} -> 1 | R3: {=IF(MOD(COLUMN()-1,4)<2, IF(AND(ROW()>=INDEX($A$22:$KN$22, COLUMN()), ROW()<INDEX($A$22:$KN$22, COLUMN())+4), 0, 1), 0)} -> 1 | S3: {=IF(MOD(COLUMN()-1,4)<2, IF(AND(ROW()>=INDEX($A$22:$KN$22, COLUMN()), ROW()<INDEX($A$22:$KN$22, COLUMN())+4), 0, 1), 0)} -> 0 | T3: {=IF(MOD(COLUMN()-1,4)<2, IF(AND(ROW()>=INDEX($A$22:$KN$22, COLUMN()), ROW()<INDEX($A$22:$KN$22, COLUMN())+4), 0, 1), 0)} -> 0 | U3: {=IF(MOD(COLUMN()-1,4)<2, IF(AND(ROW()>=INDEX($A$22:$KN$22, COLUMN()), ROW()<INDEX($A$22:$KN$22, COLUMN())+4), 0, 1), 0)} -> 1 | V3: {=IF(MOD(COLUMN()-1,4)<2, IF(AND(ROW()>=INDEX($A$22:$KN$22, COLUMN()), ROW()<INDEX($A$22:$KN$22, COLUMN())+4), 0, 1), 0)} -> 1 | W3: {=IF(MOD(COLUMN()-1,4)<2, IF(AND(ROW()>=INDEX($A$22:$KN$22, COLUMN()), ROW()<INDEX($A$22:$KN$22, COLUMN())+4), 0, 1), 0)} -> 0 | X3: {=IF(MOD(COLUMN()-1,4)<2, IF(AND(ROW()>=INDEX($A$22:$KN$22, COLUMN()), ROW()<INDEX($A$22:$KN$22, COLUMN())+4), 0, 1), 0)} -> 0 | ... AL3: {=IF(MOD(COLUMN()-1,4)<2, IF(AND(ROW()>=INDEX($A$22:$KN$22, COLUMN()), ROW()<INDEX($A$22:$KN$22, COLUMN())+4), 0, 1), 0)} -> 1 | AM3: {=IF(MOD(COLUMN()-1,4)<2, IF(AND(ROW()>=INDEX($A$22:$KN$22, COLUMN()), ROW()<INDEX($A$22:$KN$22, COLUMN())+3), 0, 1), 0)} -> 0 | AN3: {=IF(MOD(COLUMN()-1,4)<2, IF(AND(ROW()>=INDEX($A$22:$KN$22, COLUMN()), ROW()<INDEX($A$22:$KN$22, COLUMN())+3), 0, 1), 0)} -> 0 | AO3: {=IF(MOD(COLUMN()-1,4)<2, IF(AND(ROW()>=INDEX($A$22:$KN$22, COLUMN()), ROW()<INDEX($A$22:$KN$22, COLUMN())+3), 0, 1), 0)} -> 1 | AP3: {=IF(MOD(COLUMN()-1,4)<2, IF(AND(ROW()>=INDEX($A$22:$KN$22, COLUMN()), ROW()<INDEX($A$22:$KN$22, COLUMN())+3), 0, 1), 0)} -> 1 | AQ3: {=IF(MOD(COLUMN()-1,4)<2, IF(AND(ROW()>=INDEX($A$22:$KN$22, COLUMN()), ROW()<INDEX($A$22:$KN$22, COLUMN())+3), 0, 1), 0)} -> 0 | AR3: {=IF(MOD(COLUMN()-1,4)<2, IF(AND(ROW()>=INDEX($A$22:$KN$22, COLUMN()), ROW()<INDEX($A$22:$KN$22, COLUMN())+3), 0, 1), 0)} -> 0 | AS3: {=IF(MOD(COLUMN()-1,4)<2, IF(AND(ROW()>=INDEX($A$22:$KN$22, COLUMN()), ROW()<INDEX($A$22:$KN$22, COLUMN())+3), 0, 1), 0)} -> 1 | AT3: {=IF(MOD(COLUMN()-1,4)<2, IF(AND(ROW()>=INDEX($A$22:$KN$22, COLUMN()), ROW()<INDEX($A$22:$KN$22, COLUMN())+3), 0, 1), 0)} -> 1 | ... BX3: {=IF(MOD(COLUMN()-1,4)<2, IF(AND(ROW()>=INDEX($A$22:$KN$22, COLUMN()), ROW()<INDEX($A$22:$KN$22, COLUMN())+3), 0, 1), 0)} -> 0 | BY3: {=IF(MOD(COLUMN()-1,4)<2, IF(AND(ROW()>=INDEX($A$22:$KN$22, COLUMN()), ROW()<INDEX($A$22:$KN$22, COLUMN())+2), 0, 1), 0)} -> 1 | BZ3: {=IF(MOD(COLUMN()-1,4)<2, IF(AND(ROW()>=INDEX($A$22:$KN$22, COLUMN()), ROW()<INDEX($A$22:$KN$22, COLUMN())+2), 0, 1), 0)} -> 1 | CA3: {=IF(MOD(COLUMN()-1,4)<2, IF(AND(ROW()>=INDEX($A$22:$KN$22, COLUMN()), ROW()<INDEX($A$22:$KN$22, COLUMN())+2), 0, 1), 0)} -> 0 | CB3: {=IF(MOD(COLUMN()-1,4)<2, IF(AND(ROW()>=INDEX($A$22:$KN$22, COLUMN()), ROW()<INDEX($A$22:$KN$22, COLUMN())+2), 0, 1), 0)} -> 0 | CC3: {=IF(MOD(COLUMN()-1,4)<2, IF(AND(ROW()>=INDEX($A$22:$KN$22, COLUMN()), ROW()<INDEX($A$22:$KN$22, COLUMN())+2), 0, 1), 0)} -> 1 | CD3: {=IF(MOD(COLUMN()-1,4)<2, IF(AND(ROW()>=INDEX($A$22:$KN$22, COLUMN()), ROW()<INDEX($A$22:$KN$22, COLUMN())+2), 0, 1), 0)} -> 1 | CE3: {=IF(MOD(COLUMN()-1,4)<2, IF(AND(ROW()>=INDEX($A$22:$KN$22, COLUMN()), ROW()<INDEX($A$22:$KN$22, COLUMN())+2), 0, 1), 0)} -> 0 | CF3: {=IF(MOD(COLUMN()-1,4)<2, IF(AND(ROW()>=INDEX($A$22:$KN$22, COLUMN()), ROW()<INDEX($A$22:$KN$22, COLUMN())+2), 0, 1), 0)} -> 0 | ... KN3: {=IF(MOD(COLUMN()-1,4)<2, IF(AND(ROW()>=INDEX($A$22:$KN$22, COLUMN()), ROW()<INDEX($A$22:$KN$22, COLUMN())+2), 0, 1), 0)} -> 0
A4: 0 | B4: 0 | C4: {=IF(MOD(COLUMN()-1,4)<2, IF(AND(ROW()>=INDEX($A$22:$KN$22, COLUMN()), ROW()<INDEX($A$22:$KN$22, COLUMN())+3), 0, 1), 0)} -> 0 | D4: {=IF(MOD(COLUMN()-1,4)<2, IF(AND(ROW()>=INDEX($A$22:$KN$22, COLUMN()), ROW()<INDEX($A$22:$KN$22, COLUMN())+3), 0, 1), 0)} -> 0 | E4: {=IF(MOD(COLUMN()-1,4)<2, IF(AND(ROW()>=INDEX($A$22:$KN$22, COLUMN()), ROW()<INDEX($A$22:$KN$22, COLUMN())+5), 0, 1), 0)} -> 1 | F4: {=IF(MOD(COLUMN()-1,4)<2, IF(AND(ROW()>=INDEX($A$22:$KN$22, COLUMN()), ROW()<INDEX($A$22:$KN$22, COLUMN())+5), 0, 1), 0)} -> 1 | G4: {=IF(MOD(COLUMN()-1,4)<2, IF(AND(ROW()>=INDEX($A$22:$KN$22, COLUMN()), ROW()<INDEX($A$22:$KN$22, COLUMN())+5), 0, 1), 0)} -> 0 | H4: {=IF(MOD(COLUMN()-1,4)<2, IF(AND(ROW()>=INDEX($A$22:$KN$22, COLUMN()), ROW()<INDEX($A$22:$KN$22, COLUMN())+5), 0, 1), 0)} -> 0 | I4: {=IF(MOD(COLUMN()-1,4)<2, IF(AND(ROW()>=INDEX($A$22:$KN$22, COLUMN()), ROW()<INDEX($A$22:$KN$22, COLUMN())+5), 0, 1), 0)} -> 1 | J4: {=IF(MOD(COLUMN()-1,4)<2, IF(AND(ROW()>=INDEX($A$22:$KN$22, COLUMN()), ROW()<INDEX($A$22:$KN$22, COLUMN())+5), 0, 1), 0)} -> 1 | K4: {=IF(MOD(COLUMN()-1,4)<2, IF(AND(ROW()>=INDEX($A$22:$KN$22, COLUMN()), ROW()<INDEX($A$22:$KN$22, COLUMN())+5), 0, 1), 0)} -> 0 | L4: {=IF(MOD(COLUMN()-1,4)<2, IF(AND(ROW()>=INDEX($A$22:$KN$22, COLUMN()), ROW()<INDEX($A$22:$KN$22, COLUMN())+5), 0, 1), 0)} -> 0 | ... N4: {=IF(MOD(COLUMN()-1,4)<2, IF(AND(ROW()>=INDEX($A$22:$KN$22, COLUMN()), ROW()<INDEX($A$22:$KN$22, COLUMN())+5), 0, 1), 0)} -> 1 | O4: {=IF(MOD(COLUMN()-1,4)<2, IF(AND(ROW()>=INDEX($A$22:$KN$22, COLUMN()), ROW()<INDEX($A$22:$KN$22, COLUMN())+3), 0, 1), 0)} -> 0 | P4: {=IF(MOD(COLUMN()-1,4)<2, IF(AND(ROW()>=INDEX($A$22:$KN$22, COLUMN()), ROW()<INDEX($A$22:$KN$22, COLUMN())+3), 0, 1), 0)} -> 0 | Q4: {=IF(MOD(COLUMN()-1,4)<2, IF(AND(ROW()>=INDEX($A$22:$KN$22, COLUMN()), ROW()<INDEX($A$22:$KN$22, COLUMN())+4), 0, 1), 0)} -> 0 | R4: {=IF(MOD(COLUMN()-1,4)<2, IF(AND(ROW()>=INDEX($A$22:$KN$22, COLUMN()), ROW()<INDEX($A$22:$KN$22, COLUMN())+4), 0, 1), 0)} -> 0 | S4: {=IF(MOD(COLUMN()-1,4)<2, IF(AND(ROW()>=INDEX($A$22:$KN$22, COLUMN()), ROW()<INDEX($A$22:$KN$22, COLUMN())+4), 0, 1), 0)} -> 0 | T4: {=IF(MOD(COLUMN()-1,4)<2, IF(AND(ROW()>=INDEX($A$22:$KN$22, COLUMN()), ROW()<INDEX($A$22:$KN$22, COLUMN())+4), 0, 1), 0)} -> 0 | U4: {=IF(MOD(COLUMN()-1,4)<2, IF(AND(ROW()>=INDEX($A$22:$KN$22, COLUMN()), ROW()<INDEX($A$22:$KN$22, COLUMN())+4), 0, 1), 0)} -> 1 | V4: {=IF(MOD(COLUMN()-1,4)<2, IF(AND(ROW()>=INDEX($A$22:$KN$22, COLUMN()), ROW()<INDEX($A$22:$KN$22, COLUMN())+4), 0, 1), 0)} -> 1 | W4: {=IF(MOD(COLUMN()-1,4)<2, IF(AND(ROW()>=INDEX($A$22:$KN$22, COLUMN()), ROW()<INDEX($A$22:$KN$22, COLUMN())+4), 0, 1), 0)} -> 0 | X4: {=IF(MOD(COLUMN()-1,4)<2, IF(AND(ROW()>=INDEX($A$22:$KN$22, COLUMN()), ROW()<INDEX($A$22:$KN$22, COLUMN())+4), 0, 1), 0)} -> 0 | ... AL4: {=IF(MOD(COLUMN()-1,4)<2, IF(AND(ROW()>=INDEX($A$22:$KN$22, COLUMN()), ROW()<INDEX($A$22:$KN$22, COLUMN())+4), 0, 1), 0)} -> 1 | AM4: {=IF(MOD(COLUMN()-1,4)<2, IF(AND(ROW()>=INDEX($A$22:$KN$22, COLUMN()), ROW()<INDEX($A$22:$KN$22, COLUMN())+3), 0, 1), 0)} -> 0 | AN4: {=IF(MOD(COLUMN()-1,4)<2, IF(AND(ROW()>=INDEX($A$22:$KN$22, COLUMN()), ROW()<INDEX($A$22:$KN$22, COLUMN())+3), 0, 1), 0)} -> 0 | AO4: {=IF(MOD(COLUMN()-1,4)<2, IF(AND(ROW()>=INDEX($A$22:$KN$22, COLUMN()), ROW()<INDEX($A$22:$KN$22, COLUMN())+3), 0, 1), 0)} -> 1 | AP4: {=IF(MOD(COLUMN()-1,4)<2, IF(AND(ROW()>=INDEX($A$22:$KN$22, COLUMN()), ROW()<INDEX($A$22:$KN$22, COLUMN())+3), 0, 1), 0)} -> 1 | AQ4: {=IF(MOD(COLUMN()-1,4)<2, IF(AND(ROW()>=INDEX($A$22:$KN$22, COLUMN()), ROW()<INDEX($A$22:$KN$22, COLUMN())+3), 0, 1), 0)} -> 0 | AR4: {=IF(MOD(COLUMN()-1,4)<2, IF(AND(ROW()>=INDEX($A$22:$KN$22, COLUMN()), ROW()<INDEX($A$22:$KN$22, COLUMN())+3), 0, 1), 0)} -> 0 | AS4: {=IF(MOD(COLUMN()-1,4)<2, IF(AND(ROW()>=INDEX($A$22:$KN$22, COLUMN()), ROW()<INDEX($A$22:$KN$22, COLUMN())+3), 0, 1), 0)} -> 1 | AT4: {=IF(MOD(COLUMN()-1,4)<2, IF(AND(ROW()>=INDEX($A$22:$KN$22, COLUMN()), ROW()<INDEX($A$22:$KN$22, COLUMN())+3), 0, 1), 0)} -> 1 | ... BX4: {=IF(MOD(COLUMN()-1,4)<2, IF(AND(ROW()>=INDEX($A$22:$KN$22, COLUMN()), ROW()<INDEX($A$22:$KN$22, COLUMN())+3), 0, 1), 0)} -> 0 | BY4: {=IF(MOD(COLUMN()-1,4)<2, IF(AND(ROW()>=INDEX($A$22:$KN$22, COLUMN()), ROW()<INDEX($A$22:$KN$22, COLUMN())+2), 0, 1), 0)} -> 1 | BZ4: {=IF(MOD(COLUMN()-1,4)<2, IF(AND(ROW()>=INDEX($A$22:$KN$22, COLUMN()), ROW()<INDEX($A$22:$KN$22, COLUMN())+2), 0, 1), 0)} -> 1 | CA4: {=IF(MOD(COLUMN()-1,4)<2, IF(AND(ROW()>=INDEX($A$22:$KN$22, COLUMN()), ROW()<INDEX($A$22:$KN$22, COLUMN())+2), 0, 1), 0)} -> 0 | CB4: {=IF(MOD(COLUMN()-1,4)<2, IF(AND(ROW()>=INDEX($A$22:$KN$22, COLUMN()), ROW()<INDEX($A$22:$KN$22, COLUMN())+2), 0, 1), 0)} -> 0 | CC4: {=IF(MOD(COLUMN()-1,4)<2, IF(AND(ROW()>=INDEX($A$22:$KN$22, COLUMN()), ROW()<INDEX($A$22:$KN$22, COLUMN())+2), 0, 1), 0)} -> 1 | CD4: {=IF(MOD(COLUMN()-1,4)<2, IF(AND(ROW()>=INDEX($A$22:$KN$22, COLUMN()), ROW()<INDEX($A$22:$KN$22, COLUMN())+2), 0, 1), 0)} -> 1 | CE4: {=IF(MOD(COLUMN()-1,4)<2, IF(AND(ROW()>=INDEX($A$22:$KN$22, COLUMN()), ROW()<INDEX($A$22:$KN$22, COLUMN())+2), 0, 1), 0)} -> 0 | CF4: {=IF(MOD(COLUMN()-1,4)<2, IF(AND(ROW()>=INDEX($A$22:$KN$22, COLUMN()), ROW()<INDEX($A$22:$KN$22, COLUMN())+2), 0, 1), 0)} -> 0 | ... KN4: {=IF(MOD(COLUMN()-1,4)<2, IF(AND(ROW()>=INDEX($A$22:$KN$22, COLUMN()), ROW()<INDEX($A$22:$KN$22, COLUMN())+2), 0, 1), 0)} -> 0
A5: 0 | B5: 0 | C5: {=IF(MOD(COLUMN()-1,4)<2, IF(AND(ROW()>=INDEX($A$22:$KN$22, COLUMN()), ROW()<INDEX($A$22:$KN$22, COLUMN())+3), 0, 1), 0)} -> 0 | D5: {=IF(MOD(COLUMN()-1,4)<2, IF(AND(ROW()>=INDEX($A$22:$KN$22, COLUMN()), ROW()<INDEX($A$22:$KN$22, COLUMN())+3), 0, 1), 0)} -> 0 | E5: {=IF(MOD(COLUMN()-1,4)<2, IF(AND(ROW()>=INDEX($A$22:$KN$22, COLUMN()), ROW()<INDEX($A$22:$KN$22, COLUMN())+5), 0, 1), 0)} -> 1 | F5: {=IF(MOD(COLUMN()-1,4)<2, IF(AND(ROW()>=INDEX($A$22:$KN$22, COLUMN()), ROW()<INDEX($A$22:$KN$22, COLUMN())+5), 0, 1), 0)} -> 1 | G5: {=IF(MOD(COLUMN()-1,4)<2, IF(AND(ROW()>=INDEX($A$22:$KN$22, COLUMN()), ROW()<INDEX($A$22:$KN$22, COLUMN())+5), 0, 1), 0)} -> 0 | H5: {=IF(MOD(COLUMN()-1,4)<2, IF(AND(ROW()>=INDEX($A$22:$KN$22, COLUMN()), ROW()<INDEX($A$22:$KN$22, COLUMN())+5), 0, 1), 0)} -> 0 | I5: {=IF(MOD(COLUMN()-1,4)<2, IF(AND(ROW()>=INDEX($A$22:$KN$22, COLUMN()), ROW()<INDEX($A$22:$KN$22, COLUMN())+5), 0, 1), 0)} -> 1 | J5: {=IF(MOD(COLUMN()-1,4)<2, IF(AND(ROW()>=INDEX($A$22:$KN$22, COLUMN()), ROW()<INDEX($A$22:$KN$22, COLUMN())+5), 0, 1), 0)} -> 1 | K5: {=IF(MOD(COLUMN()-1,4)<2, IF(AND(ROW()>=INDEX($A$22:$KN$22, COLUMN()), ROW()<INDEX($A$22:$KN$22, COLUMN())+5), 0, 1), 0)} -> 0 | L5: {=IF(MOD(COLUMN()-1,4)<2, IF(AND(ROW()>=INDEX($A$22:$KN$22, COLUMN()), ROW()<INDEX($A$22:$KN$22, COLUMN())+5), 0, 1), 0)} -> 0 | ... N5: {=IF(MOD(COLUMN()-1,4)<2, IF(AND(ROW()>=INDEX($A$22:$KN$22, COLUMN()), ROW()<INDEX($A$22:$KN$22, COLUMN())+5), 0, 1), 0)} -> 1 | O5: {=IF(MOD(COLUMN()-1,4)<2, IF(AND(ROW()>=INDEX($A$22:$KN$22, COLUMN()), ROW()<INDEX($A$22:$KN$22, COLUMN())+3), 0, 1), 0)} -> 0 | P5: {=IF(MOD(COLUMN()-1,4)<2, IF(AND(ROW()>=INDEX($A$22:$KN$22, COLUMN()), ROW()<INDEX($A$22:$KN$22, COLUMN())+3), 0, 1), 0)} -> 0 | Q5: {=IF(MOD(COLUMN()-1,4)<2, IF(AND(ROW()>=INDEX($A$22:$KN$22, COLUMN()), ROW()<INDEX($A$22:$KN$22, COLUMN())+4), 0, 1), 0)} -> 0 | R5: {=IF(MOD(COLUMN()-1,4)<2, IF(AND(ROW()>=INDEX($A$22:$KN$22, COLUMN()), ROW()<INDEX($A$22:$KN$22, COLUMN())+4), 0, 1), 0)} -> 0 | S5: {=IF(MOD(COLUMN()-1,4)<2, IF(AND(ROW()>=INDEX($A$22:$KN$22, COLUMN()), ROW()<INDEX($A$22:$KN$22, COLUMN())+4), 0, 1), 0)} -> 0 | T5: {=IF(MOD(COLUMN()-1,4)<2, IF(AND(ROW()>=INDEX($A$22:$KN$22, COLUMN()), ROW()<INDEX($A$22:$KN$22, COLUMN())+4), 0, 1), 0)} -> 0 | U5: {=IF(MOD(COLUMN()-1,4)<2, IF(AND(ROW()>=INDEX($A$22:$KN$22, COLUMN()), ROW()<INDEX($A$22:$KN$22, COLUMN())+4), 0, 1), 0)} -> 1 | V5: {=IF(MOD(COLUMN()-1,4)<2, IF(AND(ROW()>=INDEX($A$22:$KN$22, COLUMN()), ROW()<INDEX($A$22:$KN$22, COLUMN())+4), 0, 1), 0)} -> 1 | W5: {=IF(MOD(COLUMN()-1,4)<2, IF(AND(ROW()>=INDEX($A$22:$KN$22, COLUMN()), ROW()<INDEX($A$22:$KN$22, COLUMN())+4), 0, 1), 0)} -> 0 | X5: {=IF(MOD(COLUMN()-1,4)<2, IF(AND(ROW()>=INDEX($A$22:$KN$22, COLUMN()), ROW()<INDEX($A$22:$KN$22, COLUMN())+4), 0, 1), 0)} -> 0 | ... AL5: {=IF(MOD(COLUMN()-1,4)<2, IF(AND(ROW()>=INDEX($A$22:$KN$22, COLUMN()), ROW()<INDEX($A$22:$KN$22, COLUMN())+4), 0, 1), 0)} -> 1 | AM5: {=IF(MOD(COLUMN()-1,4)<2, IF(AND(ROW()>=INDEX($A$22:$KN$22, COLUMN()), ROW()<INDEX($A$22:$KN$22, COLUMN())+3), 0, 1), 0)} -> 0 | AN5: {=IF(MOD(COLUMN()-1,4)<2, IF(AND(ROW()>=INDEX($A$22:$KN$22, COLUMN()), ROW()<INDEX($A$22:$KN$22, COLUMN())+3), 0, 1), 0)} -> 0 | AO5: {=IF(MOD(COLUMN()-1,4)<2, IF(AND(ROW()>=INDEX($A$22:$KN$22, COLUMN()), ROW()<INDEX($A$22:$KN$22, COLUMN())+3), 0, 1), 0)} -> 1 | AP5: {=IF(MOD(COLUMN()-1,4)<2, IF(AND(ROW()>=INDEX($A$22:$KN$22, COLUMN()), ROW()<INDEX($A$22:$KN$22, COLUMN())+3), 0, 1), 0)} -> 1 | AQ5: {=IF(MOD(COLUMN()-1,4)<2, IF(AND(ROW()>=INDEX($A$22:$KN$22, COLUMN()), ROW()<INDEX($A$22:$KN$22, COLUMN())+3), 0, 1), 0)} -> 0 | AR5: {=IF(MOD(COLUMN()-1,4)<2, IF(AND(ROW()>=INDEX($A$22:$KN$22, COLUMN()), ROW()<INDEX($A$22:$KN$22, COLUMN())+3), 0, 1), 0)} -> 0 | AS5: {=IF(MOD(COLUMN()-1,4)<2, IF(AND(ROW()>=INDEX($A$22:$KN$22, COLUMN()), ROW()<INDEX($A$22:$KN$22, COLUMN())+3), 0, 1), 0)} -> 1 | AT5: {=IF(MOD(COLUMN()-1,4)<2, IF(AND(ROW()>=INDEX($A$22:$KN$22, COLUMN()), ROW()<INDEX($A$22:$KN$22, COLUMN())+3), 0, 1), 0)} -> 1 | ... BX5: {=IF(MOD(COLUMN()-1,4)<2, IF(AND(ROW()>=INDEX($A$22:$KN$22, COLUMN()), ROW()<INDEX($A$22:$KN$22, COLUMN())+3), 0, 1), 0)} -> 0 | BY5: {=IF(MOD(COLUMN()-1,4)<2, IF(AND(ROW()>=INDEX($A$22:$KN$22, COLUMN()), ROW()<INDEX($A$22:$KN$22, COLUMN())+2), 0, 1), 0)} -> 1 | BZ5: {=IF(MOD(COLUMN()-1,4)<2, IF(AND(ROW()>=INDEX($A$22:$KN$22, COLUMN()), ROW()<INDEX($A$22:$KN$22, COLUMN())+2), 0, 1), 0)} -> 1 | CA5: {=IF(MOD(COLUMN()-1,4)<2, IF(AND(ROW()>=INDEX($A$22:$KN$22, COLUMN()), ROW()<INDEX($A$22:$KN$22, COLUMN())+2), 0, 1), 0)} -> 0 | CB5: {=IF(MOD(COLUMN()-1,4)<2, IF(AND(ROW()>=INDEX($A$22:$KN$22, COLUMN()), ROW()<INDEX($A$22:$KN$22, COLUMN())+2), 0, 1), 0)} -> 0 | CC5: {=IF(MOD(COLUMN()-1,4)<2, IF(AND(ROW()>=INDEX($A$22:$KN$22, COLUMN()), ROW()<INDEX($A$22:$KN$22, COLUMN())+2), 0, 1), 0)} -> 1 | CD5: {=IF(MOD(COLUMN()-1,4)<2, IF(AND(ROW()>=INDEX($A$22:$KN$22, COLUMN()), ROW()<INDEX($A$22:$KN$22, COLUMN())+2), 0, 1), 0)} -> 1 | CE5: {=IF(MOD(COLUMN()-1,4)<2, IF(AND(ROW()>=INDEX($A$22:$KN$22, COLUMN()), ROW()<INDEX($A$22:$KN$22, COLUMN())+2), 0, 1), 0)} -> 0 | CF5: {=IF(MOD(COLUMN()-1,4)<2, IF(AND(ROW()>=INDEX($A$22:$KN$22, COLUMN()), ROW()<INDEX($A$22:$KN$22, COLUMN())+2), 0, 1), 0)} -> 0 | ... KN5: {=IF(MOD(COLUMN()-1,4)<2, IF(AND(ROW()>=INDEX($A$22:$KN$22, COLUMN()), ROW()<INDEX($A$22:$KN$22, COLUMN())+2), 0, 1), 0)} -> 0
